Workbook
Name __FDS_HYPERLINK_TOGGLE_STATE__: "ON"
Name __IntlFixup: TRUE
Name _Order1: 255
Name _Order2: 255
Name _Regression_Int: 1
Name AccessDatabase: "C:\accts\AUD97_98.mdb"
Name anscount: 2
Name AS2DocOpenMode: "AS2DocumentEdit"
Name AS2HasNoAutoHeaderFooter: " "
Name AS2NamedRange: 2
Name AS2ReportLS: 1
Name AS2VersionLS: 300
Name BG_Del: 15
Name BG_Ins: 4
Name BG_Mod: 6
Name bkj: {"'Sheet1'!$A$5:$E$42"}
Name bkj: {"'Sheet1'!$A$5:$E$42"}
Name cenvat: {"'August 2000'!$A$1:$J$101"}
Name cenvat: {"'August 2000'!$A$1:$J$101"}
Name crador: {"'kpi2-1'!$E$4"}
Name crador: {"'kpi2-1'!$E$4"}
Name csczd: 0
Name dhakjs: {"'August 2000'!$A$1:$J$101"}
Name dhakjs: {"'August 2000'!$A$1:$J$101"}
Name EV__LASTREFTIME__: 40035.4476736111
Name Ext_EP: {"'kpi2-1'!$E$4"}
Name Ext_EP: {"'kpi2-1'!$E$4"}
Name gejsdfngjkosdnm: {"'Sheet1'!$A$5:$E$42"}
Name gejsdfngjkosdnm: {"'Sheet1'!$A$5:$E$42"}
Name H_1: {"'Sheet1'!$A$5:$E$42"}
Name H_1: {"'Sheet1'!$A$5:$E$42"}
Name H_1_1: {"'Sheet1'!$A$5:$E$42"}
Name H_1_1: {"'Sheet1'!$A$5:$E$42"}
Name H_1_2: {"'Sheet1'!$A$5:$E$42"}
Name H_1_2: {"'Sheet1'!$A$5:$E$42"}
Name H_1_3: {"'Sheet1'!$A$5:$E$42"}
Name H_1_3: {"'Sheet1'!$A$5:$E$42"}
Name H_2: {"'Sheet1'!$A$5:$E$42"}
Name H_2: {"'Sheet1'!$A$5:$E$42"}
Name H_3: {"'Sheet1'!$A$5:$E$42"}
Name H_3: {"'Sheet1'!$A$5:$E$42"}
Name H_4: {"'Sheet1'!$A$5:$E$42"}
Name H_4: {"'Sheet1'!$A$5:$E$42"}
Name html: {"'kpi2-1'!$E$4"}
Name html: {"'kpi2-1'!$E$4"}
Name HTML_CodePage: 949
Name HTML_CodePage: 1252
Name HTML_Control: {"'kpi2-1'!$E$4"}
Name HTML_Control: {"'I-1 and I-2'!$A$1:$G$190"}
Name HTML_Control: {"'kpi2-1'!$E$4"}
Name HTML_Control_1: {"'August 2000'!$A$1:$J$101"}
Name HTML_Control_1: {"'August 2000'!$A$1:$J$101"}
Name HTML_Control_1_1: {"'Sheet1'!$A$5:$E$42"}
Name HTML_Control_1_1: {"'Sheet1'!$A$5:$E$42"}
Name HTML_Control_1_2: {"'Sheet1'!$A$5:$E$42"}
Name HTML_Control_1_2: {"'Sheet1'!$A$5:$E$42"}
Name HTML_Control_1_3: {"'Sheet1'!$A$5:$E$42"}
Name HTML_Control_1_3: {"'Sheet1'!$A$5:$E$42"}
Name HTML_Control_2: {"'Sheet1'!$A$5:$E$42"}
Name HTML_Control_2: {"'Sheet1'!$A$5:$E$42"}

Sheet BS
B2: Balance Sheet as at 31 March 2025
B3: (Amounts are stated in ₹ lakhs, except share and per share data, unless ottherwise stated) | H3: BS | I3: =E31-E64 -> -0.081383736 | J3: =F31-F64 -> -0.22206287
H4: Cash flow | I4: =Cashflow!D50-Cashflow!D58 -> -0.30940571 | J4: =Cashflow!E50-Cashflow!E58 -> 0.002824503
B5: Particulars | C5: Notes | E5: As at 31 March 2025 | F5: As at 31 March 2024
B7: Assets
B9: Non-current assets
B10: Property,plant and equipment | C10: ='3-4'!A5 -> 3 | E10: ='3-4'!H28 -> 381.66709 | F10: ='3-4'!H29 -> 589.31208
B11: Other Intangible assets | C11: ='3-4'!A33 -> 4 | E11: ='3-4'!E56 -> 3913.8615 | F11: ='3-4'!E57 -> 3214.71
B12: Right-of-use of assets | C12: ='Leases 29'!A5 -> 29 | E12: ='Leases 29'!E33 -> 752.24662 | F12: ='Leases 29'!E34 -> 754.68761
B13: Intangible assets under development | C13: ='3-4'!A33 -> 4 | E13: ='3-4'!D56 -> 0 | F13: ='3-4'!D57 -> 589
B14: Other intangible assets | C14: ='3-4'!A33 -> 4 | E14: ='Standalone TB'!X182+'Standalone TB'!X175 -> 0 | F14: 0
B15: Financial assets
B16: Other financial assets | C16: ='5-7'!A6 -> 5 | E16: ='5-7'!D17 -> 443.52744 | F16: ='5-7'!E17 -> 773
B17: Deferred tax assets (net) | C17: ='26-27'!A5 -> 26 | E17: ='26-27'!F90 -> 398.71987 | F17: ='26-27'!G120 -> 398.51987
B18: Income tax assets (net) | C18: ='26-27'!A5 -> 26 | E18: ='26-27'!F72 -> 981.25818 | F18: ='26-27'!G72 -> 1849.6468
B19: Total non-current assets | D19: =SUM(D10:D18) -> 0 | E19: =SUM(E10:E18) -> 6871.2807 | F19: =SUM(F10:F18)+1 -> 8169.8763
B21: Current assets
B22: Financial assets
B23: Investments | C23: 7 | D23: 0 | E23: 0 | F23: 0
B24: Trade receivables | C24: ='8-10'!$A$5 -> 8 | E24: ='8-10'!I17 -> 9350.3619 | F24: ='8-10'!$J$17 -> 11738.93
B25: Cash and cash equivalents | C25: ='8-10'!$A$53 -> 9 | E25: ='8-10'!$I$60 -> 5497.6528 | F25: ='8-10'!$J$60 -> 3886.7736
B26: Bank balances other than cash and cash equivalents above | C26: ='8-10'!A67 -> 10 | E26: ='8-10'!$I$70 -> 2.402056 | F26: ='8-10'!$J$70 -> 2247.8618
B27: Other financial assets | C27: ='5-7'!A6 -> 5 | E27: ='5-7'!D25 -> 204.39541 | F27: ='5-7'!E25 -> 129
B28: Other current assets | C28: ='5-7'!A30 -> 6 | E28: ='5-7'!D45 -> 2176.4271 | F28: ='5-7'!E45 -> 2591.132
B29: Total current assets | D29: =SUM(D22:D28) -> 0 | E29: =SUM(E24:E28) -> 17231.239 | F29: =SUM(F22:F28) -> 20593.697
B31: Total assets | D31: =+D19+D29 -> 0 | E31: =+E19+E29 -> 24102.52 | F31: =+F19+F29 -> 28763.573
B34: Equity and liabilities
B36: Equity
B37: Share capital | C37: ='11-13'!$A$5 -> 11 | E37: =('11-13'!H28+'11-13'!H35) -> 50.6183 | F37: =5061830/10^5 -> 50.6183
B38: Other equity | C38: ='11-13'!$A$109 -> 12 | E38: ='11-13'!G113 -> 11476.706 | F38: ='11-13'!H113 -> 11364.975
B39: c) Share application pending allotment | C39: 12 | D39: 0 | E39: 0 | F39: 0
B40: Total equity | D40: =SUM(D37:D39) -> 0 | E40: =SUM(E37:E39) -> 11527.325 | F40: =SUM(F37:F39)+0.3 -> 11415.893
B42: Liabilities
B43: Non-current liabilities
B44: Employee benefit obligations | C44: ='11-13'!$A$142 -> 13 | E44: ='11-13'!G146 -> 0 | F44: ='11-13'!H146 -> 897.06919
B45: Financial liabilities
B46: Lease liabilities | C46: ='Leases 29'!A5 -> 29 | E46: ='Leases 29'!$D$81 -> 691.50412 | F46: ='Leases 29'!E81 -> 690.21247
B47: b) Other long-term liabilities | E47: 0 | F47: 0
B48: Total non-current liabilities | D48: =SUM(D44:D47) -> 0 | E48: =SUM(E44:E47) -> 691.50412 | F48: =SUM(F44:F47) -> 1587.2817
B50: Current liabilities
...

Sheet Cash flow Working
A1: Paladion Networks Private Limited | AI1: Legends:
A2: Cash Flow Statement for the year ended 31 March 2023 | AI2: a | AJ2: Traced from CY FS
AI3: b | AJ3: Traced from PY FS
AI4: e | AJ4: Recomputed
A7: Particulars | B7: Cash Flow | C7: Share Capital | D7: Securities premium | E7: Retained earning | F7: Current Year Profit | G7: Employee benefit obligations (Non- Current) | H7: Employee benefit obligations (Current) | I7: Lease liabilities | J7: Trade payables | K7: Other financial liabilities | L7: Other current liabilities | N7: Property, Plant and Equipment | O7: Other intangible assets | P7: CWIP-Internal Software Development | Q7: Right-of-use of assets | R7: Security deposits (Current) | S7: Security deposits (Non-Current) | T7: Deposits with banks (Non-Current) | U7: Deposits with banks (Current) | V7: Interest accrued on deposits (Non-Current) | W7: Interest accrued on deposits (Current) | X7: Deferred tax assets (Non-Current) | Y7: Lease receivable(Non -Current) | Z7: Advance tax (Non-Current) | AA7: Trade receivables | AB7: Advance to suppliers (Current) | AC7: Loans and advance to employees (Current) | AD7: Receivable from related parties | AE7: Other receivables | AF7: Balance with government authorities (Current) | AG7: Prepaid expenses (Current) | AH7: Cash effect | AI7: Total
A8: Balance 31 March 2025 (Amount in INR) | C8: =-'11-13'!F18 -> -50.6183 | D8: =-'11-13'!G125 -> -41916.54 | E8: =E10 -> 30551.565 | F8: =-F9 -> -111.73127 | G8: ='11-13'!G146 -> 0 | H8: =-'11-13'!G152 -> -1329.9226 | I8: =-'Leases 29'!D83 -> -1018.2465 | J8: =-'14-16'!I16 -> -5145.4797 | K8: =-'14-16'!I53 -> -4189.1737 | L8: =-'14-16'!I67 -> -892.45427 | N8: ='3-4'!H28 -> 381.66709 | O8: ='3-4'!E56 -> 3913.8615 | P8: ='3-4'!D56 -> 0 | Q8: =BS!E12 -> 752.24662 | R8: ='5-7'!D22 -> 181.35703 | S8: ='5-7'!D12+'5-7'!D11 -> 172.52744 | T8: ='5-7'!D13 -> 31 | U8: ='5-7'!D23+'8-10'!I69 -> 25.402056 | V8: ='5-7'!D14 -> 1 | W8: ='5-7'!D24 -> 0.038374 | X8: ='26-27'!F90 -> 398.71987 | Y8: ='5-7'!D16 -> 239 | Z8: =BS!E18 -> 981.25818 | AA8: ='8-10'!I17 -> 9350.3619 | AB8: ='5-7'!D44 -> 0 | AC8: ='5-7'!D41 -> 20.809125 | AD8: ='5-7'!D39 -> 142.90723 | AE8: ='5-7'!D40 -> 101.11986 | AF8: ='5-7'!D42 -> 1617.808 | AG8: ='5-7'!D43 -> 293.78288 | AH8: ='8-10'!I60 -> 5497.6528 | AI8: =SUM(C8:AH8) -> -0.081383736 | AJ8: a
B9: =-PL!D45 -> -111.73127 | F9: =-B9 -> 111.73127 | AI9: 0
A10: Balance 31 March 2024 (Amount in INR) | C10: =-'11-13'!H18 -> -50.6183 | D10: =-'11-13'!H125 -> -41916.54 | E10: =-'11-13'!H134 -> 30551.565 | G10: =-'11-13'!H146 -> -897.06919 | H10: =-'11-13'!H152 -> -467.33622 | I10: =-'Leases 29'!E83 -> -1004.7865 | J10: =-'14-16'!J16 -> -8391.2828 | K10: =-'14-16'!J53 -> -5272.3365 | L10: =-'14-16'!J67 -> -1315.111 | N10: ='3-4'!H29 -> 589.31208 | O10: ='3-4'!E57 -> 3214.71 | P10: ='3-4'!D57 -> 589 | Q10: ='Leases 29'!C34 -> 754.68761 | R10: ='5-7'!E22 -> 120 | S10: ='5-7'!E12+'5-7'!E11 -> 216 | T10: ='5-7'!E13 -> 170 | U10: ='5-7'!E23+'8-10'!J69 -> 2249.8618 | V10: ='5-7'!E14 -> 12 | W10: ='5-7'!E24 -> 7 | X10: ='26-27'!G90 -> 398.71987 | Y10: ='5-7'!E16 -> 375 | Z10: =BS!F18 -> 1849.6468 | AA10: ='8-10'!J17 -> 11738.93 | AB10: ='5-7'!E44 -> 39.614499 | AC10: ='5-7'!E41 -> 39.911882 | AD10: ='5-7'!E39 -> 1978.3663 | AE10: ='5-7'!E40+1 -> 41.237245 | AF10: ='5-7'!E42 -> 372.40413 | AG10: ='5-7'!E43 -> 120.59794 | AH10: ='8-10'!J60 -> 3886.7736 | AI10: =SUM(B10:AH10) -> 0.25793713 | AJ10: b
A11: Change during the year | B11: =B10-B8-B9 -> 111.73127 | C11: =C10-C8-C9 -> 0 | D11: =D10-D8-D9 -> 0 | E11: =E10-E8-E9 -> 0 | G11: =G10-G8-G9 -> -897.06919 | H11: =H10-H8-H9 -> 862.58639 | I11: =I10-I8-I9 -> 13.459945 | J11: =J10-J8-J9 -> -3245.8031 | K11: =K10-K8-K9 -> -1083.1627 | L11: =L10-L8-L9 -> -422.65675 | N11: =N10-N8-N9 -> 207.64498 | O11: =O10-O8-O9 -> -699.1515 | P11: =P10-P8-P9 -> 589 | Q11: =Q10-Q8-Q9 -> 2.4409936 | R11: =R10-R8-R9 -> -61.357035 | S11: =S10-S8-S9 -> 43.472556 | T11: =T10-T8-T9 -> 139 | U11: =U10-U8-U9 -> 2224.4597 | ... AI11: =AI10-AI8-AI9 -> 0.33932087 | AJ11: e
A12: Non Cash adjustments in balance sheet | AI12: =SUM(B12:AH12) -> 0
A13: Transfer to Gratuity | B13: =-SUM(C13:AH13) -> 115.36426 | G13: =-PL!D37 -> -115.36426 | X13: =PL!D38 -> 0 | AI13: =SUM(B13:AH13) -> 0
A14: Tax charge | B14: =-SUM(C14:AH14) -> 0 | X14: =-PL!D28 -> 0 | AI14: =SUM(B14:AH14) -> 0
A15: Reclass | B15: =-SUM(C15:AH15) -> 0 | O15: =589 -> 589 | P15: =-589 -> -589 | R15: =0 -> 0 | V15: =-V11 -> -11 | W15: =-V15 -> 11 | Y15: =-Q15 -> 0 | AI15: =SUM(B15:AH15) -> 0
A16: New leases | B16: =-SUM(C16:AH16) -> 0 | I16: =-'Leases 29'!D70 -> -379.14853 | Q16: =-I16 -> 379.14853 | AI16: =SUM(B16:AH16) -> 0
A17: Transfer of Security Deposit to RoU As prepaid asset | B17: =-SUM(C17:AH17) -> 0 | Q17: =143847.940133968/10^5 -> 1.4384794 | S17: =-Q17 -> -1.4384794 | AI17: =SUM(B17:AH17) -> 0
A18: Modification of lease | B18: =-SUM(C18:AH18) -> 0 | AI18: =SUM(B18:AH18) -> 0
B19: =-SUM(C19:AH19) -> 0 | AI19: =SUM(B19:AH19) -> 0
A20: Profit Before Tax, prior period and exceptional | B20: =SUM(B11:B18) -> 227.09553
A21: Exceptional items | B21: =-SUM(C21:AH21) -> 0
A22: Profit Before Tax, prior period | B22: =B20+B21 -> 227.09553
A23: Non-cash items | AI23: =SUM(B23:AH23) -> 0
A24: Depreciation and amortization | B24: =-SUM(C24:AH24) -> 2477.7009 | N24: =-'17-25'!$D$139 -> -183.31775 | O24: =-'3-4'!E51 -> -1952.3551 | Q24: =-'17-25'!D141 -> -342.02812 | AI24: =SUM(B24:AH24) -> 0
A25: Finance income on financial assets measured at amortised cost | B25: =-SUM(C25:AH25) -> -27.46033 | Q25: =0 -> 0 | Y25: ='17-25'!C80/10^5 -> 27.46033 | AI25: =SUM(B25:AH25) -> 0
A26: Provision for diminushing investments in Subsidiary | B26: =-SUM(C26:AH26) -> 0 | AI26: =SUM(B26:AH26) -> 0
A27: Interest income on bank deposits | B27: =-SUM(C27:AH27) -> 0 | AI27: =SUM(B27:AH27) -> 0
A28: Exchange impact | B28: =-SUM(C28:AH28) -> 0 | AI28: =SUM(B28:AH28) -> 0
A29: Finance cost | B29: =-SUM(C29:AH29) -> 106.28668 | I29: =-'Leases 29'!E71 -> -106.28668 | AI29: =SUM(B29:AH29) -> 0
A30: Provision for doubtful trade receivables(net of reversal/utilisation) | B30: =-SUM(C30:AH30) -> 26.32863 | AA30: =-'17-25'!D177 -> -26.32863 | AI30: =SUM(B30:AH30) -> 0
A31: Provision / liabilities no longer required written back | B31: =-SUM(C31:AH31) -> 0 | AI31: =SUM(B31:AH31) -> 0
A32: Gain on sublease/sale of PPE | B32: =-SUM(C32:AH32) -> 0 | AI32: =SUM(B32:AH32) -> 0
AI33: =SUM(B33:AH33) -> 0
A34: Increase/Decrease in Current Assets and Liabilities | AI34: =SUM(B34:AH34) -> 0
A35: Movement of working capital | AI35: =SUM(B35:AH35) -> 0
A36: Decrease/(Increase) in trade receivables | B36: =-SUM(C36:AH36) -> 2362.2392 | AA36: =-AA11-AA30 -> -2362.2392 | AI36: =SUM(B36:AH36) -> 0
A37: Decrease/(Increase) in bank balance other than cash and cash equivalent | B37: =-SUM(C37:AH37) -> 0 | AI37: =SUM(B37:AH37) -> 0
A38: Decrease/(Increase) in loans and advances | B38: =-SUM(C38:AH38) -> 19.102757 | AC38: =-AC11 -> -19.102757 | AI38: =SUM(B38:AH38) -> 0
A39: Decrease/(Increase) in Other financial assets | B39: =-SUM(C39:AH39) -> 39.614499 | AB39: =-AB11 -> -39.614499 | AI39: =SUM(B39:AH39) -> 0
A40: Decrease/(Increase) in other assets | B40: =-SUM(C40:AH40) -> 356.98764 | AD40: =-AD11 -> -1835.459 | AE40: =-AE11 -> 59.882612 | AF40: =-AF11 -> 1245.4039 | AG40: =-AG11 -> 173.18494 | AI40: =SUM(B40:AH40) -> 0
A41: (Decrease)/Increase in trade payables | B41: =-SUM(C41:AH41) -> -3245.8031 | J41: =-J11 -> 3245.8031 | AI41: =SUM(B41:AH41) -> 0
A42: (Decrease)/Increase in other financial liabilities | B42: =-SUM(C42:AH42) -> -1144.5198 | K42: =-K11 -> 1083.1627 | R42: =-R11 -> 61.357035 | AI42: =SUM(B42:AH42) -> 0
...

Sheet PL
B2: Statement of Profit and Loss for the year ended 31 March 2025
B3: =BS!B3 -> (Amounts are stated in ₹ lakhs, except share and per share data, unless ottherwise stated)
B5: Particulars | C5: Notes | D5: For the year ended 31 March 2025 | E5: For the year ended 31 March 2024
B7: Revenue
B8: Revenue from contracts with the customers | C8: ='17-25'!$A$5 -> 17 | D8: ='17-25'!D12 -> 23301.29 | E8: ='17-25'!E12 -> 28077.967 | F8: =D8/E8-1 -> -0.1701219 | H8: =D8*10^5 -> 2.330129e+09
B9: Other Income | C9: ='17-25'!$A$73 -> 18 | D9: ='17-25'!D90 -> 261.95673 | E9: ='17-25'!E90 -> 385.02038 | F9: =D9/E9-1 -> -0.31962891 | H9: =D9*10^5 -> 26195673
B10: Total Income | D10: =SUM(D8:D9) -> 23563.246 | E10: =SUM(E8:E9) -> 28462.987 | H10: =SUM(H8:H9) -> 2.3563246e+09
B12: Expenses
B13: Cost of software packages | C13: ='17-25'!$A$93 -> 19 | D13: ='17-25'!D97 -> 1483.5182 | E13: ='17-25'!E97 -> 1510.2087 | F13: =D13/E13-1 -> -0.017673401 | H13: =D13*10^5 -> 1.4835182e+08
B14: Technical contract charges | C14: ='17-25'!$A$99 -> 20 | D14: ='17-25'!D104 -> 7381.0085 | E14: ='17-25'!E104 -> 8924.3992 | F14: =D14/E14-1 -> -0.17294057 | H14: =D14*10^5 -> 7.3810085e+08
B15: Employee benefits expense | C15: ='17-25'!$A$110 -> 21 | D15: ='17-25'!D121 -> 8727.4152 | E15: ='17-25'!E121 -> 11030.44 | F15: =D15/E15-1 -> -0.20878812 | H15: =D15*10^5 -> 8.7274152e+08
B16: Finance costs | C16: ='17-25'!$A$123 -> 22 | D16: ='17-25'!D133 -> 140.66685 | E16: ='17-25'!E133 -> 92.783532 | F16: =D16/E16-1 -> 0.51607558 | H16: =D16*10^5 -> 14066685
B17: Depreciation and amortisation | C17: ='17-25'!$A$137 -> 23 | D17: ='17-25'!D142 -> 2477.7009 | E17: ='17-25'!E142 -> 740.7639 | F17: =D17/E17-1 -> 2.3447917 | H17: =D17*10^5 -> 2.4777009e+08
B18: Other expenses | C18: ='17-25'!$A$151 -> 24 | D18: ='17-25'!D190 -> 2702.0666 | E18: ='17-25'!E190 -> 2956 | F18: =D18/E18-1 -> -0.0859044 | H18: =D18*10^5 -> 2.7020666e+08
B19: Total expenses | D19: =SUM(D13:D18) -> 22912.376 | E19: =SUM(E13:E18)-1 -> 25253.595 | H19: =SUM(H13:H18) -> 2.2912376e+09
B21: Profit / (Loss) before exceptional items and tax | D21: =D10-D19 -> 650.87006 | E21: =E10-E19 -> 3209.3917
B22: Exceptional item | C22: ='17-25'!A201 -> 25 | D22: ='17-25'!D203 -> 0 | E22: 18242
B23: (Loss) before tax | D23: =D21-D22 -> 650.87006 | E23: =E21-E22 -> -15032.608 | H23: =D23*10^5 -> 65087006
H24: =H10-H19 -> 65087006
B25: Tax expense
B26: Current tax | C26: ='26-27'!A5 -> 26 | D26: ='26-27'!$F$14 -> 654.50305 | E26: 8.6358
B27: Prior year's tax adjustments | D27: 0 | E27: 0
B28: Deferred tax charge / (credit) | C28: ='26-27'!A5 -> 26 | D28: =0 -> 0 | E28: 1082.1538
D29: =SUM(D26:D28) -> 654.50305 | E29: =SUM(E26:E28) -> 1090.7896
B31: (Loss) / Profit for the year after tax | D31: =D23-D29 -> -3.6329941 | E31: =E23-E29 -> -16123.398 | H31: =D31*10^5 -> -363299.41
B35: Other comprehensive income / (loss)
B36: (i) Items that will not be reclassified to profit or loss
A37: OCI | B37: - Remeasurment of defined benefit plan | D37: =-SUMIF('Standalone TB'!$Z:$Z,PL!A37,'Standalone TB'!$X:$X)/10^5 -> 115.36426 | E37: 49.89188
B38: - Income tax relating to above | D38: =-D37*0 -> 0 | E38: -12.556788
B40: (ii) Items that will be reclassified to profit or loss
B41: - Income tax relating to above | D41: - | E41: -
B43: Other comprehensive income / (loss) for the year (net of tax) | D43: =SUM(D37:D38) -> 115.36426 | E43: =SUM(E37:E38) -> 37.335092
B45: Total comprehensive (loss) / income for the year (net of tax) | D45: =D31+D43 -> 111.73127 | E45: =E31+E43 -> -16086.063 | F45: =ROUND(D45,0) -> 112 | H45: =D45*10^5 -> 11173127 | I45: =SUMIF('Standalone TB'!D:D,"PL",'Standalone TB'!X:X) -> -11173127 | J45: =H45+I45 -> -1.2852252e-07
C47: 26
B48: Basic earnings per equity share (Face value of ₹ 10 each) | D48: ='26-27'!$F$130 -> -36.329941 | E48: ='26-27'!$G$130 -> -161241.98
B49: Diluted Earnings per equity share (Face value of ₹ 10 each) | D49: ='26-27'!$F$133 -> 0 | E49: ='26-27'!$G$133 -> -3.8410993
B51: Summary of material accounting policies | C51: 2 | E51: =E49-E12 -> -3.8410993
B52: The accompanying notes are an integral part of the financial statements
B53: As per our report of even date
B55: For Walker Chandiok & Co LLP | D55: For and on behalf of the Board of Directors of
...

Sheet SOCE 
B1: Paladion Networks Private Limited
B2: Statement of Change in Equity for the year ended 31 March 2025
B3: =PL!B3 -> (Amounts are stated in ₹ lakhs, except share and per share data, unless ottherwise stated)
B5: (A) Share capital
B7: Particulars | E7: Note | F7: No. of shares | G7: Amount
B8: Issued, subscribed and fully paid up
B9: Equity shares of ₹ 10 each | E9: ='11-13'!$A$5 -> 11
B10: Property and equipment
B11: Balance as at 31 March 2023 | F11: ='11-13'!G24 -> 10000 | G11: =F11*10/10^5 -> 1
B12: Changes in equity share capital during the year | F12: - | G12: -
B13: Balance as at 31 March 2024 | F13: =SUM(F11:F12) -> 10000 | G13: =SUM(G11:G12) -> 1
B14: Changes in equity share capital during the year | F14: - | G14: -
B15: Balance as at 31 March 2025 | F15: =SUM(F13:F14) -> 10000 | G15: =SUM(G13:G14) -> 1
B17: Preference shares of ₹ 10 each | E17: ='11-13'!$A$5 -> 11
B19: Balance as at 31 March 2023 | F19: ='11-13'!E17 -> 496183 | G19: =F19*10/10^5 -> 49.6183
B20: Changes in equity share capital during the year | F20: ='11-13'!G32 -> 0 | G20: =(F20*10)/10^5 -> 0
B21: Balance as at 31 March 2024 | F21: =SUM(F19:F20) -> 496183 | G21: =SUM(G19:G20) -> 49.6183
B22: Changes in equity share capital during the year | F22: 0 | G22: 0
B23: Balance as at 31 March 2025 | F23: =SUM(F21:F22) -> 496183 | G23: =SUM(G21:G22) -> 49.6183
B26: (B) Other equity (Refer Note 12) | E26: Reserves and Surplus
B28: Particulars | E28: Securities Premium | F28: Retained earnings | G28: Total
B29: =B11 -> Balance as at 31 March 2023 | E29: ='11-13'!H123 -> 41916.54 | F29: ='11-13'!H131 -> -14464.702 | G29: =SUM(E29:F29) -> 27451.838
B30: Profit for the year | E30: - | F30: ='11-13'!H132 -> -16124.198 | G30: =SUM(E30:F30) -> -16124.198
B31: Other comprehensive loss | E31: - | F31: ='11-13'!H133 -> 37.335092 | G31: =SUM(E31:F31) -> 37.335092
B32: Additions during the year | E32: - | F32: - | G32: -
B33: =B13 -> Balance as at 31 March 2024 | E33: =SUM(E29:E32) -> 41916.54 | F33: =SUM(F29:F32)+0.1 -> -30551.465 | G33: =SUM(G29:G32) -> 11364.975 | H33: =F33*10^5 -> -3.0551465e+09 | I33: =SUMIF('Standalone TB'!Z:Z,"Retained earnings",'Standalone TB'!X:X) -> 3.0551465e+09 | J33: =H33+I33 -> 0
B34: Profit for the year | E34: 0 | F34: ='11-13'!G132 -> -3.6329941 | G34: =SUM(E34:F34) -> -3.6329941
B35: Other comprehensive loss | E35: 0 | F35: ='11-13'!G133 -> 115.36426 | G35: =SUM(E35:F35) -> 115.36426
B36: Additions during the year | E36: 0 | F36: 0 | G36: 0
B37: =B15 -> Balance as at 31 March 2025 | E37: =SUM(E33:E36) -> 41916.54 | F37: =SUM(F33:F36) -> -30439.734 | G37: =SUM(G33:G36)+0.5 -> 11477.206
B39: This is the Statement of Changes in Equity referred to in our report of even date
B41: The accompanying notes are an integral part of the financial statements
B42: As per our report of even date
B44: For Walker Chandiok & Co LLP | F44: For and on behalf of the Board of Directors of
B45: Chartered Accountants | F45: Paladion Networks Private Limited
B46: Firm's Registration No: 001076N/N500013 | F46: CIN: U72200TN2018FTC120862
B50: =PL!#REF! -> #REF! | F50: Arvind Jugalkishor Bajaj | G50: =PL!#REF! -> #REF!
B51: =PL!#REF! -> #REF! | F51: Director | G51: =PL!#REF! -> #REF!
B52: =PL!#REF! -> #REF! | F52: DIN : 08051490 | G52: =PL!#REF! -> #REF!
B54: =PL!#REF! -> #REF! | F54: Place: Mumbai | G54: Place: Mumbai
...

Sheet Cashflow
B1: ='SOCE '!B1 -> Paladion Networks Private Limited
B2: Statement of Cash Flow for the year ended 31 March 2025
B3: ='SOCE '!B3 -> (Amounts are stated in ₹ lakhs, except share and per share data, unless ottherwise stated)
B5: Particulars | D5: Year ended 31 March 2025 | E5: Year ended 31 March 2024
B7: Cash flow from operating activities
B8: Profit before tax | D8: ='Cash flow Working'!B20 -> 227.09553 | E8: -14942.46 | AA8: =D8-Z8 -> 227.09553
B9: Adjustments to reconcile loss before tax to net cashflow :
B10: Depreciation and amortization | D10: ='Cash flow Working'!B24 -> 2477.7009 | E10: 740.7639
B11: Impairmemt of Goodwill | D11: =PL!D22 -> 0 | E11: 18242
B12: Provision for diminution (other than temporary) in value of investments | D12: =0 -> 0 | E12: 54.567653
B13: Interest income on bank deposits | D13: ='Cash flow Working'!B27 -> 0 | E13: 0
B14: Finance income on financial assets measured at amortised cost | D14: =+'Cash flow Working'!B25 -> -27.46033 | E14: -20.082086
B15: Unrealised exchange impact | D15: ='Cash flow Working'!B28 -> 0 | E15: 0
B16: Finance charges under leases | D16: ='Cash flow Working'!B29 -> 106.28668 | E16: 67.661123
B17: Provision / liabilities no longer required written back | D17: ='Cash flow Working'!B31 -> 0 | E17: 0
B18: Provision for doubtful trade receivables and advances(net of reversal/utilisation) | D18: ='17-25'!D177 -> 26.32863 | E18: -77
B19: Gain on sublease | D19: ='Cash flow Working'!B32 -> 0 | E19: -66.197828
B20: Operating profit/(loss) before working capital changes | D20: =SUM(D8:D19) -> 2809.9514 | E20: =SUM(E8:E19) -> 3999.2524
B22: Working Capital Adjustments:
B23: Decrease/(Increase) in trade receivables | D23: ='Cash flow Working'!B36 -> 2362.2392 | E23: -2659
B24: Decrease/(Increase) in loans and advances | D24: ='Cash flow Working'!B38 -> 19.102757 | E24: -32.413883
B25: Decrease/(Increase) in other financial assets | D25: ='Cash flow Working'!B39 -> 39.614499 | E25: -39.614499
B26: Decrease/(Increase) in other assets | D26: ='Cash flow Working'!B40 -> 356.98764 | E26: -1403.3933
B27: (Decrease)/Increase in trade payables | D27: ='Cash flow Working'!B41 -> -3245.8031 | E27: 1392.9887
B28: (Decrease)/Increase in other financial liabilities | D28: ='Cash flow Working'!B42 -> -1144.5198 | E28: 3733.9804
B29: (Decrease)/Increase in other liabilities | D29: ='Cash flow Working'!B43 -> -422.65675 | E29: 37.29762
B30: (Decrease)/Increase in provisions | D30: ='Cash flow Working'!B44 -> -149.84706 | E30: 197.7424
B31: Operating profit after working capital changes | D31: =SUM(D20:D30)+0.5 -> 625.56891 | E31: =SUM(E20:E30)+0.7 -> 5227.5398
B32: Taxes paid (taxes refund received) | D32: ='Cash flow Working'!B46 -> 868.38859 | E32: 5.6546934
B33: Net cash generated from operating activities (A) | D33: =SUM(D31:D32)+0.4 -> 1494.3575 | E33: =SUM(E31:E32)+1 -> 5234.1945
B35: Cash flow from investing activities
B37: Purchase of property, plant and equipment | D37: ='Cash flow Working'!B49 -> -2079.336 | E37: -4216.5908
B38: Proceeds from sale of property,plant and equipment | D38: ='Cash flow Working'!B50 -> 41.52816 | E38: 4.00035
B39: Interest received on deposits | D39: ='Cash flow Working'!B51 -> 17.961626 | E39: 3.209044
B40: Investment in deposits | D40: ='Cash flow Working'!B52 -> 2405.4938 | E40: -2382.0539
B41: Net cash generated/ (used in) investing activities (B) | D41: =SUM(D37:D40)-0.1 -> 385.54755 | E41: =SUM(E37:E40)-1 -> -6592.4354
B43: Cash flow from financing activities
B44: Payment of finance lease liability | D44: ='Cash flow Working'!B54 -> -432.80307 | E44: -309.16161
B45: Receipt of finance lease | D45: ='Cash flow Working'!B55 -> 163.465
B46: Net cash used in financing activities (C) | D46: =SUM(D44:D45) -> -269.33807 | E46: =SUM(E44:E44) -> -309.16161
...

Sheet Note 1-2
B1: Paladion Networks Private Limited
B2: Summary of material accounting policies and other explanatory information
B5: 1 | C5: General information
C6: Paladion Networks Private Limited (‘the Company’) is a Company incorporated on February 16, 2018 under the provisions of the Companies Act, 2013.The Company is in the business of providing assurance services, compliance services, risk mitigation services, training services, on-site security management and other consultancy services relating to networking and development of software products.
B7: 2 | C7: Summary of material accounting policies :
B9: 2.1 | C9: Basis of preparation and presentation of financial statements
C10: The standalone financial statements have been prepared in all material aspect with an Indian Accounting Standards (Ind AS) notified under Sec 133 of Companies Act 2013 and Companies (accounting standards) Rules, 2015 have been prepared on a the historical cost basis except for certain financial instruments that are measured at fair values at the end of each reporting period, as explained in the accounting policies below.
C11: Monetary amounts are expressed in Indian Rupee (₹) and are rounded off to millions, except for earning per share. Due to rounding off, the numbers presented throughout the document may not add up precisely to the totals and percentages may not precisely reflect the absolute figures.
C12: The Company has uniformly applied the accounting policies during the period presented. The Standalone Financial statements correspond to the classification provisions contained in Ind AS 1 "Presentation of financial statement" for clarity various items are aggregated in the statement of profit and loss and balance sheet. These items are disaggregated separately in the notes to the financial statement where applicable.
B14: 2.2 | C14: Significant management judgements and estimates
C16: The preparation of the financial statements in conformity with generally accepted accounting requires management to make estimates, judgements and assumptions. These estimates, judgements and assumptions affect the application of accounting policies and the reported amounts of assets and liabilities, the disclosures of contingent liabilities at the date of the financial statements and reported amounts of revenues and expenses during the period. Accounting estimates could change from period to period. Actual results could differ from those estimates. Appropriate changes in estimates are made as management becomes aware of changes in circumstances surrounding the estimates. Changes in estimates are reflected in the financial statements in the period in which changes are made and, if material, their effects are disclosed in the notes to the financial statements.
C18: The following are significant management judgements / estimates in applying the accounting policies of the Company that have the most significant effect on the financial statements.
C20: Expected cost of completing fixed price contracts
C21: The Company uses the percentage-of-completion method in accounting for its fixed-price contracts. Use of the percentage-of-completion method requires the Company to estimate the efforts or costs expended to date as a proportion of the total efforts or costs to be expended. Efforts or costs expended have been used to measure progress towards completion as there is a direct relationship between input and productivity. Estimated cost to be incurred are derived by way of budgeting process and assessing the input and productivity. Provisions for estimated losses, if any, on uncompleted contracts are recorded in the period in which such losses become probable based on the expected contract estimates at the reporting date.
C23: Liquidated damages
C24: Company assesses the ability of the Company to deliver contracts within budgeted timelines and exposures. Liquidated damages for late delivery are computed on the basis on contract terms, history of liquidated damages and management expectation.
C26: Evaluation of principal vs agent
C27: The Company recognized revenue from resale of products, i.e. software. In this Paladion performs solution design in addition to installation or simple set-up directly linked to the resale item (ranges from 2 – 3 percent of total project value), The management has assessed that accounting for the sale of such software on gross basis is primarily on account of -
C29: (a) | D29: Paladion does take control over the software license and has risk attached to it. The Company does not have any physical inventory.
C30: (b) | D30: Paladion is the primary obligor for software in this situation as the Company does take responsibility of third-party items.
C31: (c) | D31: Services provided by the Paladion are not complex and hence it does not create separate deliverable for the customer, it only enhances the value of the product. This is not a complex implementation project which creates a composite output for the customer. Here, sale of services are separate performance obligations where the service portion is clearly identifiable and not material to the total transaction price.
C33: Recognition of deferred tax asset
C34: Deferred tax assets are recognized to the extent that it is probable that the underlying tax loss or deductible temporary difference will be utilized against future taxable income.
C37: Evaluation of Indicators for impairment of assets
C38: The evaluation of applicability of Indicators of impairment of assets requires assessment of several external and internal factors which could result in deterioration of recoverable amount of the assets.
C40: Useful lives of depreciable/amortisable assets
C41: Management reviews its estimate of the useful lives of depreciable/amortisable assets at each reporting date, based on the expected utility of the assets. Uncertainties in these estimates relate to technical and economic obsolescence that may change the utility of certain items of property and equipment.
C43: Defined benefit obligation(DBO)
C44: Management’s estimate of the DBO is based on a number of critical underlying assumptions such as standard rates of inflation, medical cost trends, mortality, discount rate and anticipation of future salary increases. Variation in these assumptions may significantly impact the DBO amount and the annual defined benefit expenses.
C46: Fair value measurements
C47: Management applies valuation techniques to determine the fair value of financial instruments (where active market quotes are not available) and non-financial assets. This involves developing estimates and assumptions consistent with how market participants would price the instrument. Management uses the best information available. Estimated fair values may vary from the actual prices that would be achieved in an arm’s length transaction at the reporting date.
C49: Provisions and liabilities
C50: Provisions and liabilities are recognized in the period when it becomes probable that there will be a future outflow of funds resulting from past operations or events that can reasonably be estimated. The timing of recognition requires application of judgement to existing facts and circumstances which may be subject to change. The amounts are determined by discounting the expected future cash flows at a pre-tax rate that reflects current market assessments of the time value of money and the risks specific to the liability.
... C58: The principal risks that the Company is impacted include uncertainty around delay in awarding the projects under negotiation by government and private customers, compliance with service level arrangement and related liquidated damages outflow, increase in discounts to customer as well as credit risk that might arise due to adverse market conditions on account of COVID 19 pandemic. The uncertainties arising from the aforesaid risk are mitigated primarily on account of certain ongoing long-term revenue agreement as well as constant monitoring of the cash in and cash out ratio. Further, the Company quickly adopted to alternate business continuity scenario, including but not limited to detailed monitoring of compliance with service level agreement and Work From Home (WFH) in near to medium term, the uncertainty still prevail in respect of timelines for resumption of normal workings conditions. Notwithstanding these safeguards, the business has drawn up contingency plans for reduction of operating expenses. In preparation of these results, the Company has taken into account internal and external sources of information to assess possible impacts of the pandemic, including but not limited to assessment of liquidity and going concern, recoverable values of its financial and non-financial assets, impact on revenues and estimates of operating costs. Based on current indicators of future economic conditions, the Company has sufficient liquidity and expects to fully recover the carrying amount of its assets. In addition, the management has reasonable expectation that the Company has adequate resources to continue in operational existence for the foreseeable future, being a period of not less than twelve months from the date of approval of these financial statements. The Company therefore continues to adopt the going concern basis in preparing its financial statements. However, due to the evolving nature of the pandemic, its actual impact in future could be different from that estimated as at the date of approval of these financial results. The Company will continue to monitor any material changes to future economic conditions.
B60: Paladion Networks Private Limited
B61: Summary of material accounting policies and other explanatory information
B64: 2.2 | C64: Significant management judgements and estimates (Contd.)
C66: Estimated value and useful life of ROU asset
C67: Ind AS 116 defines a lease term as the non-cancellable period for which the lessee has the right to use an underlying asset including optional periods, when an entity is reasonably certain to exercise an option to extend (or not to terminate) a lease. The Company considers all relevant facts and circumstances that create an economic incentive for the lessee to exercise the option when determining the lease term. The option to extend the lease term is included in the lease term, if it is reasonably certain that the lessee would exercise the option. The Company reassesses the option when significant events or changes in circumstances occur that are within the control of the lessee. The lease term in future periods is reassessed to ensure that the lease term reflects the current economic circumstances. The Company has applied an incremental borrowing rate for the purpose of computing lease liabilities based on the rate prevailing in India.
B81: (Space left blank intentionally)
...

Sheet 3-4
B1: ='SOCE '!B1 -> Paladion Networks Private Limited
B2: Summary of Material accounting policies and other explanatory information
B3: ='SOCE '!B3 -> (Amounts are stated in ₹ lakhs, except share and per share data, unless ottherwise stated)
A5: 3 | B5: ="Note "&A5&": Property,plant and equipment" -> Note 3: Property,plant and equipment
C7: Building | D7: Leasehold improvements | E7: Furniture & fixtures | F7: Office equipments | G7: Computers | H7: Total
B9: Gross block
B10: As at 01 April 2023 | C10: 229.87798 | D10: 19.4365 | E10: 107.92661 | F10: 48.141443 | G10: 959.25204 | H10: =ROUND(SUM(C10:G10),2) -> 1364.63
B11: Additions | C11: - | D11: 63.64232 | E11: 109.53549 | F11: 21.896099 | G11: 3.3169341 | H11: =ROUND(SUM(C11:G11),2) -> 198.39
B12: Disposals | C12: - | D12: - | E12: -50.948056 | F12: -8.6110291 | G12: -262.50035 | H12: =ROUND(SUM(C12:G12),2) -> -322.06 | K12: Gross value of Asset sold | L12: 203.69816
B13: As at 31 March 2024 | C13: =SUM(C10:C12) -> 229.87798 | D13: =SUM(D10:D12) -> 83.07882 | E13: =SUM(E10:E12) -> 166.51404 | F13: =SUM(F10:F12) -> 61.426513 | G13: =SUM(G10:G12) -> 700.06863 | H13: =SUM(H10:H12)-0.5 -> 1240.46 | K13: Acc.dep of Asset sold | L13: -162.17
B14: Additions | C14: - | E14: =8.84505 -> 8.84505 | F14: =0.19 -> 0.19 | G14: =5.89495+1.811+0.08846 -> 7.79441 | H14: =SUM(C14:G14) -> 16.82946 | K14: Net book value of asset sold | L14: =SUM(L12:L13) -> 41.52816
B15: Disposals | C15: - | G15: =-203.69816 -> -203.69816 | H15: =SUM(C15:G15) -> -203.69816
B16: As at 31 March 2025 | C16: =SUM(C13:C15) -> 229.87798 | D16: =SUM(D13:D15) -> 83.07882 | E16: =SUM(E13:E15) -> 175.35909 | F16: =SUM(F13:F15) -> 61.616513 | G16: =SUM(G13:G15) -> 504.16488 | H16: =SUM(H13:H15) -> 1053.5913
B18: Accumulated depreciation
B19: =B10 -> As at 01 April 2023 | C19: 17.918793 | D19: 19.047226 | E19: 80.39274 | F19: 41.162229 | G19: 524.00202 | H19: =SUM(C19:G19) -> 682.523
B20: Depreciation charge for the year | C20: 4.5964025 | D20: 3.9775214 | E20: 14.534848 | F20: 8.7166786 | G20: 255.96398 | H20: =SUM(C20:G20) -> 287.78943
B21: Disposals | C21: - | D21: - | E21: -50.655344 | F21: -6.4283864 | G21: -262.08078 | H21: =SUM(C21:G21) -> -319.16451
B22: =+B13 -> As at 31 March 2024 | C22: =SUM(C19:C21) -> 22.515195 | D22: =SUM(D19:D21) -> 23.024747 | E22: =SUM(E19:E21) -> 44.272244 | F22: =SUM(F19:F21) -> 43.450521 | G22: =SUM(G19:G21) -> 517.88522 | H22: =SUM(H19:H21) -> 651.14792
B23: Depreciation charge for the year | C23: 4.5964025 | D23: 9.2972211 | E23: 24.175962 | F23: 7.0345818 | G23: =135.179618+2.11762+0.91635+0.03451 -> 138.2481 | H23: =SUM(C23:G23) -> 183.35227 | J23: ='17-25'!D139 -> 183.31775 | K23: =H23-J23 -> 0.034511203
B24: Disposals | G24: =-162.17 -> -162.17 | H24: =SUM(C24:G24) -> -162.17
B25: =+B16 -> As at 31 March 2025 | C25: =SUM(C22:C24) -> 27.111598 | D25: =SUM(D22:D24) -> 32.321969 | E25: =SUM(E22:E24) -> 68.448206 | F25: =SUM(F22:F24)+0.1 -> 50.585103 | G25: =SUM(G22:G24) -> 493.96331 | H25: =SUM(H22:H24) -> 672.33019
B27: Net block
B28: =+B16 -> As at 31 March 2025 | C28: =C16-C25 -> 202.76638 | D28: =D16-D25 -> 50.756851 | E28: =E16-E25 -> 106.91089 | F28: =F16-F25 -> 11.031411 | G28: =G16-G25 -> 10.201561 | H28: =SUM(C28:G28) -> 381.66709 | J28: =SUMIF('Standalone TB'!AB:AB,"PPE",'Standalone TB'!X:X)/10^5 -> 381.90062 | K28: =H28-J28 -> -0.23352376
B29: =+B13&"(#)" -> As at 31 March 2024(#) | C29: =C13-C22 -> 207.36278 | D29: =D13-D22 -> 60.054072 | E29: =E13-E22 -> 122.2418 | F29: =F13-F22 -> 17.975992 | G29: =G13-G22 -> 182.18341 | H29: =H13-H22 -> 589.31208
B31: #) Zero represents less than ₹0.5 Lakhs
A33: =A5+1 -> 4 | B33: ="Note "&A33&":Intangible assets" -> Note 4:Intangible assets
D34: Internal Assets Under Development | E34: Internal Software Developed | F34: Software purchased | G34: Acquired goodwill | H34: Total
B35: Gross block
B36: =B10 -> As at 01 April 2023 | D36: 0 | E36: 0 | F36: 11.23 | G36: 36484.21 | H36: =D36+E36+F36+G36 -> 36495.44
B37: Additions | D37: 589 | E37: 3429 | F37: 0 | G37: 0 | H37: =D37+E37+F37+G37 -> 4018
B38: Disposals | E38: 0 | F38: 0 | G38: 0 | H38: =E38+F38+G38 -> 0
B39: =B13 -> As at 31 March 2024 | D39: =ROUND(SUM(D36:D38),2) -> 589 | E39: =ROUND(SUM(E36:E38),2) -> 3429 | F39: =ROUND(SUM(F36:F38),2) -> 11.23 | G39: =ROUND(SUM(G36:G38),2) -> 36484.21 | H39: =ROUND(SUM(H36:H38),2) -> 40513.44
B40: Additions | D40: =ROUND('Standalone TB'!X186/10^5,0) -> 0 | E40: =2651.5065679-E41 -> 2062.5066 | F40: 0 | G40: 0 | H40: =E40+F40+G40+D40 -> 2062.5066
B41: Capitalized | D41: =-589 -> -589 | E41: =589 -> 589 | H41: =E41+F41+G41+D41 -> 0
B42: Disposals | D42: =0 -> 0 | E42: =0 -> 0 | F42: 0 | G42: 0 | H42: =E41+F42+G42+D41 -> 0
B43: =B16 -> As at 31 March 2025 | D43: =SUM(D39:D41) -> 0 | E43: =SUM(E39:E41) -> 6080.5066 | F43: =SUM(F39:F42) -> 11.23 | G43: =SUM(G39:G42) -> 36484.21 | H43: =SUM(H39:H42) -> 42575.947
B45: Accumulated amortisation
B46: =B36 -> As at 01 April 2023 | D46: 0 | E46: 0 | F46: 11.23 | G46: 18242.105 | H46: =(F46+G46+E46) -> 18253.335
B47: Amortisation charge for the year | D47: 0 | E47: 214.29473 | F47: 0 | G47: 0 | H47: =(F47+G47+E47) -> 214.29473
B48: Disposals | D48: 0 | E48: 0 | F48: 0 | G48: 0 | H48: =(F48+G48+E48) -> 0
...

Sheet 5-7
B1: ='3-4'!B1 -> Paladion Networks Private Limited
B2: ='3-4'!B2 -> Summary of Material accounting policies and other explanatory information
B3: ='3-4'!B3 -> (Amounts are stated in ₹ lakhs, except share and per share data, unless ottherwise stated)
A6: ='3-4'!A33+1 -> 5 | B6: ="Note "&A6&": Other financial assets" -> Note 5: Other financial assets
B8: Non Current | C8: As at 31 March 2025 | D8: As at 31 March 2025 | E8: As at 31 March 2024 | G8: Mar 23
B9: Unsecured, considered good | G9: FD-Margin Money | I9: FD Maturity | L9: Accrued Interest
B10: Security deposits | G10: <12M | H10: >12M | I10: <3M | J10: >3M & <12M | K10: >12M | L10: <3M | M10: <12M | N10: >12M
B11: ="- Related parties (refer note "&'30 RPT'!A5&")" -> - Related parties (refer note 30) | C11: 12436488 | D11: =C11/10^5 -> 124.36488 | E11: 117 | G11: 2266175 | H11: 2111275 | J11: =2506381-G11 -> 240206 | K11: =3072031.66-H11 -> 960756.66 | M11: 3837 | N11: 135828
A12: Security deposits | B12: - others | C12: =SUMIFS('Standalone TB'!$X:$X,'Standalone TB'!$Z:$Z,'5-7'!$A12)-C11-C22 -> 4816256.3 | D12: =C12/10^5 -> 48.162563 | E12: 99
B13: Deposits with banks (*) | C13: =H11+K11 -> 3072031.7 | D13: =ROUND(C13/10^5,0) -> 31 | E13: 170
B14: Interest accrued on deposits | C14: =N11 -> 135828 | D14: =ROUND(C14/10^5,0) -> 1 | E14: 12
B15: Lease receivable
A16: Lease receivable | B16: ="- Related parties (refer note "&'30 RPT'!A5&")" -> - Related parties (refer note 30) | C16: =SUMIFS('Standalone TB'!$X:$X,'Standalone TB'!$Z:$Z,'5-7'!$A16) -> 23935012 | D16: =ROUND(C16/10^5,0) -> 239 | E16: 375
B17: Total | C17: =SUM(C10:C16) -> 44395616 | D17: =SUM(D10:D16) -> 443.52744 | E17: =SUM(E10:E16) -> 773
B19: Current | C19: =C8 -> As at 31 March 2025 | D19: =D8 -> As at 31 March 2025 | E19: =E8 -> As at 31 March 2024
B20: Unsecured, considered good
A22: Security deposits | B22: Security deposits | C22: 18135703 | D22: =C22/10^5 -> 181.35703 | E22: 120
B23: Deposits with banks (*) | C23: =G11 -> 2266175 | D23: =ROUND(C23/10^5,0) -> 23 | E23: 2
A24: Interest accrued on deposits | B24: Interest accrued on deposits | C24: =SUMIFS('Standalone TB'!$X:$X,'Standalone TB'!$Z:$Z,'5-7'!$A24)-C14 -> 3837.4 | D24: =C24/10^5 -> 0.038374 | E24: 7
B25: Total | C25: =SUM(C22:C24) -> 20405716 | D25: =SUM(D22:D24) -> 204.39541 | E25: =SUM(E22:E24) -> 129
B27: Note:
B28: (*)Fixed deposits are kept under lien for performance bank guarantees for various projects amounting to ₹ 29 (31 March 2024 : ₹29).
A30: =A6+1 -> 6 | B30: ="Note "&A30&": Other Current assets" -> Note 6: Other Current assets
C32: Non-current | D32: =D19 -> As at 31 March 2025 | E32: =E19 -> As at 31 March 2024
B33: Unsecured, considered good
B34: Deposits with banks having maturity period of more than 12 months from the balance sheet date (refer note below) | D34: 0
B35: Interest accrued on deposits | D35: 0
B36: Advance to suppliers-
B37: - for capital goods | D37: 0
B38: - others | D38: 0
A39: Receivable from related parties | B39: ="Receivable from related parties" & " (refer note "&'30 RPT'!A5&")" -> Receivable from related parties (refer note 30) | C39: =SUMIFS('Standalone TB'!$X:$X,'Standalone TB'!$Z:$Z,'5-7'!$A39) -> 14290723 | D39: =C39/10^5 -> 142.90723 | E39: 1978.3663
A40: Other receivables | B40: Receivables form others | C40: =SUMIFS('Standalone TB'!$X:$X,'Standalone TB'!$Z:$Z,'5-7'!$A40) -> 10111986 | D40: =C40/10^5 -> 101.11986 | E40: 40.237245
A41: Loans & Advances to Employees | B41: Loans and advance to employees | C41: =SUMIFS('Standalone TB'!$X:$X,'Standalone TB'!$Z:$Z,'5-7'!$A41) -> 2080912.5 | D41: =C41/10^5 -> 20.809125 | E41: 39.911882
A42: Balance with govt. authorities | B42: Balance with government authorities | C42: =SUMIFS('Standalone TB'!$X:$X,'Standalone TB'!$Z:$Z,'5-7'!$A42) -> 1.617808e+08 | D42: =C42/10^5 -> 1617.808 | E42: 372.40413
A43: Prepaid | B43: Prepaid expenses | C43: =SUMIFS('Standalone TB'!$X:$X,'Standalone TB'!$Z:$Z,'5-7'!$A43) -> 29378288 | D43: =C43/10^5 -> 293.78288 | E43: 120.59794
A44: Advance to suppliers | B44: Advance to suppliers | C44: =SUMIFS('Standalone TB'!$X:$X,'Standalone TB'!$Z:$Z,'5-7'!$A44) -> 0 | D44: =C44/10^5 -> 0 | E44: 39.614499
B45: Total | C45: =SUM(C33:C44) -> 2.1764271e+08 | D45: =SUM(D33:D44) -> 2176.4271 | E45: =SUM(E33:E44) -> 2591.132
A47: =A30+1 -> 7 | B47: ="Note "&A47&": Investments" -> Note 7: Investments
C48: =C19 -> As at 31 March 2025 | D48: =D32 -> As at 31 March 2025 | E48: =E32 -> As at 31 March 2024
B49: Non-current
...

Sheet 8-10
B1: ='3-4'!B1 -> Paladion Networks Private Limited | N1: ER | O1: 23.2939 | P1: 85.563771
B2: ='3-4'!B2 -> Summary of Material accounting policies and other explanatory information
B3: ='3-4'!B3 -> (Amounts are stated in ₹ lakhs, except share and per share data, unless ottherwise stated)
P4: -
A5: ='5-7'!A47+1 -> 8 | B5: ="Note "&A5&": Trade receivables" -> Note 8: Trade receivables | M5: 355868.54 | N5: 4.3960565e+08
H6: As at 31 March 2025 | I6: As at 31 March 2025 | J6: As at 31 March 2024
B7: Trade receivables considered good - secured | I7: 0 | J7: 0
B8: Trade receivables considered good - unsecured | N8: India | O8: Sharjah | P8: US | Q8: Total
B9: ="- Related parties (refer note "&'30 RPT'!A5&")" -> - Related parties (refer note 30) | H9: =ROUND(SUM(Q9:Q11),0) -> 519781051 | I9: =(SUM(H9:H9))/10^5 -> 5197.8105 | J9: 8621.049 | K9: =ROUND(J9,0) -> 8621 | L9: Done | M9: IR | N9: =439605648.39+355868.54 -> 4.3996152e+08 | O9: =(35863055.71-465059.225)*$O$1 -> 8.245574e+08 | P9: =17200*P1 -> 1471696.9 | Q9: =SUM(N9:P9) -> 1.2659906e+09
A10: Debtors | B10: - Others | H10: =SUMIFS('Standalone TB'!$X:$X,'Standalone TB'!$Z:$Z,'8-10'!$A10)-H9 -> 78599307 | I10: =(SUM(H10:H10))/10^5 -> 785.99307 | J10: 1239.7168 | K10: =ROUND(J10,0) -> 1240 | M10: IR-Elimination | N10: -11837173 | O10: =-31649862.21*$O$1 -> -7.3724873e+08 | Q10: =SUM(N10:P10) -> -7.490859e+08
B11: Trade Receivables which have significant increase in credit risk | H11: =-SUM('Standalone TB'!X204:X206) -> 7549549.6 | I11: =(SUM(H11:H11))/10^5 -> 75.495496 | J11: 48.649991 | K11: =ROUND(J11,0) -> 49 | M11: IR-Forex | N11: =2876344.35 -> 2876344.4 | O11: =0 -> 0 | Q11: =SUM(N11:P11) -> 2876344.4
B12: Less: Expected credit losses (Refer note 8.2) | H12: =-H11 -> -7549549.6 | I12: =(SUM(H12:H12))/10^5 -> -75.495496 | J12: -48.649991 | K12: =ROUND(J12,0) -> -49 | M12: ER | N12: 58824055 | O12: =1201472.35*$O$1 -> 27986977 | P12: =-14458.04*P1 -> -1237084.4 | Q12: =SUM(N12:P12) -> 85573947
B13: Unbilled revenue | K13: =ROUND(J13,0) -> 0 | M13: ER-Forex | N13: =27058 -> 27058 | O13: =23519.11*$O$1 -> 547851.8 | Q13: =SUM(N13:P13) -> 574909.8 | R13: =SUM(Q9:Q13) -> 6.0592991e+08
B14: ="- Related parties (refer note "&'30 RPT'!A5&")" -> - Related parties (refer note 30) | H14: =SUM(Q15,Q16) -> 3.035998e+08 | I14: =(SUM(H14:H14))/10^5 -> 3035.998 | J14: 1532.6633 | K14: =ROUND(J14,0) -> 1533 | M14: Unbilled-ER | N14: =30421417.98+860505.38 -> 31281923 | O14: =76162*O1 -> 1774110 | Q14: =SUM(N14:P14) -> 33056033
A15: Unbilled Revenue | B15: - others | H15: =SUMIFS('Standalone TB'!$X:$X,'Standalone TB'!$Z:$Z,'8-10'!$A15)-H14 -> 33056030 | I15: =(SUM(H15:H15))/10^5 -> 330.5603 | J15: 345.5007 | K15: =ROUND(J15,0) -> 346 | M15: Unbilled -IR | N15: 3.0360936e+08 | O15: =0 -> 0 | Q15: =SUM(N15:P15) -> 3.0360936e+08
M16: Unbilled -IR-forex | N16: =-2816.09-6744 -> -9560.09 | Q16: =SUM(N16:P16) -> -9560.09
B17: Total | H17: =SUM(H7:H16) -> 9.3503619e+08 | I17: =SUM(I7:I16) -> 9350.3619 | J17: =SUM(J7:J16) -> 11738.93 | K17: =SUM(K7:K16) -> 11740 | N17: =SUM(N9:N16) -> 8.2473353e+08 | O17: =SUM(O9:O16) -> 1.176176e+08 | P17: =SUM(P9:P16) -> 234612.44 | Q17: =SUM(Q9:Q16) -> 9.4258575e+08
M18: As per TB | N18: =SUMIF('Standalone TB'!$AB:$AB,"Trade receivables",'Standalone TB'!$H:$H) -> 8.1938547e+08 | O18: =SUMIF('Standalone TB'!$AB:$AB,"Trade receivables",'Standalone TB'!$N:$N) -> 1.1541611e+08 | P18: =SUMIF('Standalone TB'!$AB:$AB,"Trade receivables",'Standalone TB'!$U:$U) -> 234612.44 | Q18: =SUMIF('Standalone TB'!$AB:$AB,"Trade receivables",'Standalone TB'!$X:$X) -> 9.3503619e+08
B19: Trade receivables are non interest bearing and are generally on terms of 30 to 90 days. | N19: =N17-N18 -> 5348059.2 | O19: =O17-O18 -> 2201494.5 | P19: =P17-P18 -> 0 | Q19: =Q17-Q18 -> 7549553.8 | R19: Provision for doubtful debts
B20: No trade receivable are due from directors or other officers of the company either severally or jointly with any other person. Nor any trade receivable are due from firms or private companies respectively in which any director is a partner, a director or a member.
A22: =A5&".1" -> 8.1 | B22: ="Note "&A22&": Trade receivables Ageing as at 31 March 2025" -> Note 8.1: Trade receivables Ageing as at 31 March 2025
D23: Outstanding for following periods from due date of payment
C24: Unbilled (not due) | D24: Total unbilled | E24: < 6 months | F24: 6 months - 1 year | G24: 1-2 years | H24: 2-3 years | I24: > 3 years | J24: Total | N24: India | O24: Sharjah | P24: US | Q24: Total
B25: Undisputed trade receivables - considered good | C25: =I15+I14 -> 3366.5583 | D25: =C25 -> 3366.5583 | E25: =Q26/10^5-E26 -> 4184.2566 | F25: =Q27/10^5-F26 -> 952.35949 | G25: =SUM(Q28/10^5) -> 844.59797 | H25: =Q29/10^5 -> 2.5895289 | I25: =Q30/10^5 -> 0 | J25: =SUM(D25:I25) -> 9350.3619
B26: Undisputed trade receivables – which have significant increase in credit risk | E26: =2082213.69374969/10^5 -> 20.822137 | F26: =5467335.87068808/10^5 -> 54.673359 | I26: =0 -> 0 | J26: =SUM(D26:I26) -> 75.495496 | M26: Less than 6 Months | N26: 3.8363694e+08 | O26: =1559338.635*$O$1+547852 -> 36870931 | Q26: =SUM(N26:P26) -> 4.2050787e+08
B27: Undisputed trade receivables – credit impaired | E27: =-E26 -> -20.822137 | F27: =-F26 -> -54.673359 | I27: 0 | J27: =SUM(D27:I27) -> -75.495496 | M27: 6 M to 1 Year | N27: 75382302 | O27: =1087022.05*O1 -> 25320983 | Q27: =SUM(N27:P27) -> 1.0070329e+08
B28: Disputed trade receivables – considered good | I28: 0 | J28: =SUM(D28:I28) -> 0 | M28: 1-2 Years | N28: 30801850 | O28: =2293447.4*O1 -> 53423335 | P28: =2741.96*P1 -> 234612.44 | Q28: =SUM(N28:P28) -> 84459797
B29: Disputed trade receivables – which have significant increase in credit risk | I29: 0 | J29: =SUM(D29:I29) -> 0 | M29: 2-3 Years | N29: 30706.68 | O29: =9798.54*O1 -> 228246.21 | Q29: =SUM(N29:P29) -> 258952.89
B30: Disputed trade receivables – credit impaired | I30: 0 | J30: =SUM(D30:I30) -> 0 | M30: More than 3 Years | Q30: =SUM(N30:P30) -> 0
B31: Total | C31: =SUM(C25:C30) -> 3366.5583 | D31: =SUM(D25:D30) -> 3366.5583 | E31: =SUM(E25:E30) -> 4184.2566 | F31: =SUM(F25:F30) -> 952.35949 | G31: =SUM(G25:G30) -> 844.59797 | H31: =SUM(H25:H30) -> 2.5895289 | I31: =SUM(I25:I30) -> 0 | J31: =SUM(J25:J30) -> 9350.3619 | M31: Total | N31: =SUM(N26:N30) -> 4.898518e+08 | O31: =SUM(O26:O30) -> 1.1584349e+08 | P31: =SUM(P26:P30) -> 234612.44 | Q31: =SUM(Q26:Q30) -> 6.0592991e+08
B33: Trade receivables Ageing as at 31 March 2024
D34: Outstanding for following periods from due date of payment | N34: =SUM(N9:N13)-N31 -> 0.22000003 | O34: =SUM(O9:O13)-O31 -> -0.19922371 | P34: =P17-P31 -> 0 | Q34: =SUM(Q9:Q13)-Q31 -> 0.020776272
C35: Unbilled (not due) | D35: Total unbilled | E35: < 6 months | F35: 6 months - 1 year | G35: 1-2 years | H35: 2-3 years | I35: > 3 years | J35: Total
B36: Undisputed trade receivables - considered good | C36: 1878.164 | D36: 1878.164 | E36: 8970.4153 | F36: 260.26892 | G36: 153.48361 | H36: 476.59799 | I36: 0 | J36: =SUM(D36:I36) -> 11738.93
B37: Undisputed trade receivables – which have significant increase in credit risk | C37: 0 | D37: 0 | E37: 44.814613 | F37: 3.835378 | G37: 0 | I37: 0 | J37: =SUM(E37:I37) -> 48.649991
B38: Undisputed trade receivables – credit impaired | C38: 0 | D38: 0 | E38: -44.814613 | F38: -3.835378 | G38: 0 | I38: 0 | J38: =SUM(E38:I38) -> -48.649991
B39: Disputed trade receivables – considered good | C39: 0 | D39: 0 | E39: 0 | F39: 0 | G39: 0 | I39: 0 | J39: =SUM(E39:I39) -> 0
B40: Disputed trade receivables – which have significant increase in credit risk | C40: 0 | D40: 0 | E40: 0 | F40: 0 | G40: 0 | I40: 0 | J40: =SUM(E40:I40) -> 0
B41: Disputed trade receivables – credit impaired | C41: 0 | D41: 0 | E41: 0 | F41: 0 | G41: 0 | I41: 0 | J41: =SUM(E41:I41) -> 0
B42: Total | C42: =SUM(C36:C41) -> 1878.164 | D42: =SUM(D36:D41) -> 1878.164 | E42: =SUM(E36:E41) -> 8970.4153 | F42: =SUM(F36:F41) -> 260.26892 | G42: =SUM(G36:G41) -> 153.48361 | H42: =SUM(H36:H41) -> 476.59799 | I42: =SUM(I36:I41) -> 0 | J42: =SUM(J36:J41) -> 11738.93
...

Sheet 11-13
B1: ='3-4'!B1 -> Paladion Networks Private Limited
B2: ='3-4'!B2 -> Summary of Material accounting policies and other explanatory information
B3: ='3-4'!B3 -> (Amounts are stated in ₹ lakhs, except share and per share data, unless ottherwise stated)
A5: ='8-10'!A67+1 -> 11 | B5: ="Note "&A5&": Share capital" -> Note 11: Share capital
C7: Authorised share capital
E8: As at 31 March 2025 | G8: As at 31 March 2024
E9: Number of shares | F9: Amount | G9: Number of shares | H9: Amount
C10: Equity shares of ₹10 each | E10: =G10 -> 10000 | F10: =H10 -> 1 | G10: 10000 | H10: =H16 -> 1
C11: Preference shares of ₹10 each | E11: =G11 -> 1000000 | F11: =H11 -> 100 | G11: 1000000 | H11: =10000000/10^5 -> 100
C13: Issued, subscribed and fully paid up
E14: =E8 -> As at 31 March 2025 | G14: =G8 -> As at 31 March 2024
E15: Number of shares | F15: Amount | G15: Number of shares | H15: Amount
C16: Equity shares of ₹10 each | E16: =G16 -> 10000 | F16: =H16 -> 1 | G16: 10000 | H16: =H28 -> 1
C17: Preference shares of ₹10 each | E17: =G17 -> 496183 | F17: =H17 -> 49.6183 | G17: 496183 | H17: =H33 -> 49.6183
E18: =SUM(E16:E17) -> 506183 | F18: =SUM(F16:F17) -> 50.6183 | G18: =SUM(G16:G17) -> 506183 | H18: =SUM(H16:H17) -> 50.6183
C20: Issued Equity share capital
B21: a) | C21: Reconciliation of shares outstanding at the beginning and at the end of the period
G22: Number of shares | H22: Amount
C23: Equity shares of ₹10 each issued, subscribed and fully paid up
C24: Balance as at 01 April 2023 | G24: 10000 | H24: =(G24*10)/10^5 -> 1
C25: Change during the year | G25: - | H25: -
C26: Balance as at 31 March 2024 | G26: =SUM(G24:G25) -> 10000 | H26: =SUM(H24:H25) -> 1
C27: Change during the year | G27: - | H27: -
C28: Shares issued and fully paid as at 31 March 2025 | G28: =SUM(G26:G27) -> 10000 | H28: =SUM(H26:H27) -> 1
C30: Equity component of preference shares of ₹10 each issued and fully paid up
C31: Balance as at 01 April 2023 | G31: 496183 | H31: =(G31*10)/10^5 -> 49.6183
C32: Change during the year | G32: 0 | H32: =(G32*10)/10^5 -> 0
C33: Balance as at 31 March 2024 | G33: =SUM(G31:G32) -> 496183 | H33: =SUM(H31:H32) -> 49.6183
C34: Change during the year | G34: - | H34: -
C35: Shares issued and fully paid as at 31 March 2025 | G35: =SUM(G33:G34) -> 496183 | H35: =SUM(H33:H34) -> 49.6183
B37: b) | C37: Rights, preferences and restrictions attached to the equity shares
C38: The Company has only one class of equity shares with voting rights (one vote per share). The Company declares and pays dividend in Indian rupees. The dividend proposed by board of directors is subject to approval by the shareholders at the ensuing annual general meeting. In the event of liquidation of the Company, the equity shareholders are entitled to receive only the residual assets of the Company after distribution of all preferential amount. The distribution will be in proportion to the number of equity shares held by the shareholder. Other rights attached to the equity shares are as per the articles of the Company.
B42: c) | C42: Rights, preferences and restrictions attached to the compulsorily convertible non-cumulative preference shares
C43: The Company has only one class of compulsorily convertible non-cumulative preference shares. In the event of liquidation of the Company, Compulsorily convertible non-cumulative preference shares will be preference over equity shareholders. The distribution will be in proportion to the number of preference shares held by the preference shareholders. Other rights attached to the preference shares are as per the articles of the Company. The shares are compulsorily convertible within 20 years from the date of allotment and are non-cumulative. The Preference shares rank ahead of Equity shares in the event of liquidation of the company.
B48: Summary of significant accounting policies and other explanatory information as at and for the year ended 31 March 2022
B49: (Amounts are stated in ₹ lakhs unless otherwise stated)
B51: d) | C51: Shares held by holding/ ultimate holding company and/ or their subsidiaries/ associates
E52: =E8 -> As at 31 March 2025 | G52: =G8 -> As at 31 March 2024
E53: Number of shares | F53: % of holding | G53: Number of shares | H53: % of holding
C54: Equity shares of ₹10 each
...

Sheet 14-16
B1: ='3-4'!B1 -> Paladion Networks Private Limited | M1: =N1*O1 -> 0 | O1: ='8-10'!O1 -> 23.2939 | P1: ='8-10'!P1 -> 85.563771
B2: ='3-4'!B2 -> Summary of Material accounting policies and other explanatory information
B3: ='3-4'!B3 -> (Amounts are stated in ₹ lakhs, except share and per share data, unless ottherwise stated)
A5: ='11-13'!A142+1 -> 14 | B5: ="Note "&A5&": Trade payables" -> Note 14: Trade payables | H5: As at 31 March 2025 | I5: As at 31 March 2025 | J5: As at 31 March 2024 | M5: Creditors | N5: India | O5: Sharjah | P5: US | Q5: Total
B7: Dues to (*) | M7: Internal | N7: =925285887.61-7208998+4519847-846292+2131502 -> 9.2388195e+08 | O7: =(4776844.01000001+3995+59042)*O1 -> 1.1273971e+08 | P7: =(310466.94)*$P$1 -> 26564722 | Q7: =SUM(N7:P7) -> 1.0631864e+09
B8: - micro enterprises and small enterprises (refer note 14.2 below) | H8: 95474.65 | I8: =(SUM(H8:H8))/10^5 -> 0.9547465 | J8: 78.55814 | M8: Internal-Elimination | N8: -7.2128282e+08 | O8: =-248959.3*O1 -> -5799233.1 | P8: =-69998.44*$P$1 -> -5989330.5 | Q8: =SUM(N8:P8) -> -7.3307139e+08
B9: - creditors other than micro enterprises and small enterprises | M9: Internal Forex | N9: =2740730.20952922 -> 2740730.2 | O9: =13403.2*O1 -> 312212.8 | Q9: =SUM(N9:P9) -> 3052943
B10: (i) To related parties (refer note 30) | H10: =SUM(Q7:Q9) -> 3.3316793e+08 | I10: =(SUM(H10:H10))/10^5 -> 3331.6793 | J10: 6409.1245 | M10: External | N10: =7735522.49-1267006 -> 6468516.5 | O10: =1188524.79*O1 -> 27685378 | P10: =4906.25*P1 -> 419797.25 | Q10: =SUM(N10:P10) -> 34573692
A11: Sundry Creditors | B11: (ii) To other than related parties | H11: =-SUMIFS('Standalone TB'!$X:$X,'Standalone TB'!$Z:$Z,'14-16'!$A11)-H8-H10-H62 -> 34445492 | I11: =(SUM(H11:H11))/10^5 -> 344.45492 | J11: 428.21045 | M11: Capex Creditors | Q11: =SUM(N11:P11) -> 0
H12: 0 | I12: =SUM(H12:H12) -> 0 | J12: 0
B13: Accrued expenses | M13: External Forex | N13: =-33148.8700000002 -> -33148.87 | O13: =18.3*O1 -> 426.27837 | Q13: =SUM(N13:P13) -> -32722.592
B14: (i) Related parties (refer note 30) | H14: 30335322 | I14: =(SUM(H14:H14))/10^5 -> 303.35322 | J14: 287.92318 | M14: Total | N14: =SUM(N7:N13) -> 2.1177522e+08 | O14: =SUM(O7:O13) -> 1.3493849e+08 | P14: =SUM(P7:P13) -> 20995189 | Q14: =SUM(Q7:Q13) -> 3.677089e+08
