Workbook
Name \0: [1]BS!#REF!
Name \a: #REF!
Name \B: #REF!
Name \b: #REF!
Name \c: #REF!
Name \d: #REF!
Name \E: #REF!
Name \f: #REF!
Name \i: #REF!
Name \m: #REF!
Name \N: #REF!
Name \P: #REF!
Name \P: #REF!
Name \Q: #REF!
Name \q: #REF!
Name \S: #REF!
Name \s: #REF!
Name ____________DAT3: [3]depit!#REF!
Name ___________DAT3: [3]depit!#REF!
Name __________DAT3: [3]depit!#REF!
Name _________DAT3: [3]depit!#REF!
Name ________DAT3: [3]depit!#REF!
Name _______DAT3: [3]depit!#REF!
Name ______8749600_Guj_State_energy: #REF!
Name ______DAT3: [3]depit!#REF!
Name _____8749600_Guj_State_energy: #REF!
Name _____DAT1: #REF!
Name _____DAT10: #REF!
Name _____DAT11: #REF!
Name _____DAT12: #REF!
Name _____DAT13: #REF!
Name _____DAT14: #REF!
Name _____DAT15: #REF!
Name _____DAT16: #REF!
Name _____DAT17: #REF!
Name _____DAT18: #REF!
Name _____DAT19: #REF!
Name _____DAT2: #REF!
Name _____DAT20: #REF!
Name _____DAT21: #REF!
Name _____DAT22: #REF!
Name _____DAT23: #REF!
Name _____DAT3: #REF!
Name _____DAT4: #REF!
Name _____DAT5: #REF!
Name _____DAT6: #REF!
Name _____DAT7: #REF!
Name _____DAT8: #REF!
Name _____DAT9: #REF!
Name ____8749600_Guj_State_energy: #REF!
Name ____DAT1: #REF!
Name ____DAT10: #REF!
Name ____DAT11: #REF!
Name ____DAT12: #REF!
Name ____DAT13: #REF!
Name ____DAT14: #REF!
Name ____DAT15: #REF!
Name ____DAT16: #REF!
Name ____DAT17: #REF!
Name ____DAT18: #REF!

Sheet Master
A2: Name of Entity | B2: Syntel Solutions (India) Private Limited
A3: Current Financial Year | B3: =YEAR(B10)&"-"&YEAR(B4) -> 2024-2025
A4: Current Period End Date | B4: 45747
A5: Formattted Current Period | B5: =IF(DAY(B4)=31,DAY(B4)&"st"&" "&TEXT(B4,"mmmm")&" "&YEAR(B4),DAY(B4)&"th"&" "&TEXT(B4,"mmmm")&" "&YEAR(B4)) -> 31st March 2025
B6: =TEXT(B4,"mmmm")&" "&DAY(B4)&", "&YEAR(B4) -> March 31, 2025
B7: =YEAR(B4) -> 2025
B8: =TEXT(B4+1,"mmmm")&" "&DAY(B4+1)&", "&YEAR(B4) -> April 1, 2025
A9: Previous Financial Year | B9: =YEAR(B16)&"-"&YEAR(B10) -> 2023-2024
A10: Prevous Period End Date | B10: =+B4-366 -> 45381
A11: Formattted Prevous Period | B11: =IF(DAY(B10)=31,DAY(B10)&"st"&" "&TEXT(B10,"mmmm")&" "&YEAR(B10),DAY(B10)&"th"&" "&TEXT(B10,"mmmm")&" "&YEAR(B10)) -> 30th March 2024
B12: =TEXT(B10,"mmmm")&" "&DAY(B10)&", "&YEAR(B10) -> March 30, 2024
B13: =YEAR(B10) -> 2024
B14: =TEXT(B10+1,"mmmm")&" "&DAY(B10+1)&", "&YEAR(B10+1) -> March 31, 2024
A15: Previous Financial Year | B15: =YEAR(B16-365)&"-"&YEAR(B16) -> 2022-2023
A16: Prevous Period End Date | B16: =+B10-365 -> 45016
A17: Formattted Prevous Period | B17: =IF(DAY(B16)=31,DAY(B16)&"st"&" "&TEXT(B16,"mmmm")&" "&YEAR(B16),DAY(B16)&"th"&" "&TEXT(B16,"mmmm")&" "&YEAR(B16)) -> 31st March 2023
B18: =TEXT(B16,"mmmm")&" "&DAY(B16)&", "&YEAR(B16) -> March 31, 2023
B19: =YEAR(B16) -> 2023
B20: =TEXT(B16+1,"mmmm")&" "&DAY(B16+1)&", "&YEAR(B16+1) -> April 1, 2023
A21: Date of Signing | B21: =TODAY() -> 46183
B22: =TEXT(B21,"mmmm")&" "&DAY(B21)&", "&YEAR(B21) -> June 10, 2026
A23: Actual amount converted into | B23: 1
B24: =IF(B23=1,"(Rs.)",IF(B23=100,"(Rs. Hundreds)",IF(B23=1000,"(Rs. Thousands)",IF(B23=100000,"(Rs. Lakhs)",IF(B23=1000000,"(Rs. Millions)",IF(B23=10000000,"(Rs. Crores)")))))) -> (Rs.)
A29: Manual | B29: Manual Input

Sheet Cover page
B6: Syntel Solutions (India) Private Limited
B9: Financial Statements
B10: For the year ended 31 March 2025
A71: Sanjay Banthia
A73: Membership No. 061068

Sheet Index
B4: Syntel Solutions (India) Private Limited
B7: Contents | I7: Page
B9: Independents Auditor's Report | I9: 3 - 10
B11: Balance Sheet | I11: 11
B13: Statement of Profit and Loss | I13: 12
B15: Cash Flow Statements | I15: 13
B17: Statements of Equity | I17: 14
B19: Summary of material accounting policies and other explanatory information | I19: 15 - 41
A70: Sanjay Banthia
A72: Membership No. 061068

Sheet Restatement
A1: =+BS!A1 -> 0
A4: (Amounts are stated in ₹ Lakhs unless otherwise stated)
A6: 1. Restatement of Balancesheet
B8: Balance Sheet as at 31 March 2019
A9: Particular | B9: Audited Balance Sheet | C9: Restatement effect | D9: Restated Balance Sheet
A10: Assets
A11: Non current assets
A12: Property and equipment | B12: =ROUND(0/Master!$B$23,0) -> 0 | D12: =+B12+C12 -> 0
A13: Capital work-in-progress | B13: =ROUND(0/Master!$B$23,0) -> 0 | D13: =+B13+C13 -> 0
A14: Intangible assets | B14: =ROUND(0/Master!$B$23,0) -> 0 | D14: =+B14+C14 -> 0
A15: Investment property | B15: =ROUND(0/Master!$B$23,0) -> 0 | D15: =+B15+C15 -> 0
A16: Financial assets
A17: Investments | B17: =ROUND(0/Master!$B$23,0) -> 0 | D17: =+B17+C17 -> 0
A18: Loans | B18: =ROUND(0/Master!$B$23,0) -> 0 | D18: =+B18+C18 -> 0
A19: Other financial assets | B19: =ROUND(1774555/Master!$B$23,0) -> 1774555 | D19: =+B19+C19 -> 1774555
A20: Deferred tax assets (net) | B20: =ROUND(16141408/Master!$B$23,0) -> 16141408 | C20: =-C100 -> 0 | D20: =+B20+C20 -> 16141408
A21: Other non-current assets | B21: =ROUND(11468027/Master!$B$23,0) -> 11468027 | D21: =+B21+C21 -> 11468027
A22: Income tax assets (net) | B22: =ROUND(41974602/Master!$B$23,0) -> 41974602 | D22: =+B22+C22 -> 41974602
A23: Total non-current assets | B23: =SUM(B12:B22) -> 71358592 | C23: =SUM(C12:C22) -> 0 | D23: =SUM(D12:D22) -> 71358592
A25: Current assets
A26: Financial assets
A27: Investments | B27: =ROUND(58216239/Master!$B$23,0) -> 58216239 | D27: =+B27+C27 -> 58216239
A28: Trade receivables | B28: =ROUND(16242010/Master!$B$23,0) -> 16242010 | D28: =+B28+C28 -> 16242010
A29: Cash and cash equivalents | B29: =ROUND(133191580/Master!$B$23,0) -> 133191580 | D29: =+B29+C29 -> 133191580
A30: Other bank balances | B30: =ROUND(0/Master!$B$23,0) -> 0 | D30: =+B30+C30 -> 0
A31: Loans | B31: =ROUND(0/Master!$B$23,0) -> 0 | D31: =+B31+C31 -> 0
A32: Other financial assets | B32: =ROUND(1523636/Master!$B$23,0) -> 1523636 | D32: =+B32+C32 -> 1523636
A33: Other current assets | B33: =ROUND(311366/Master!$B$23,0) -> 311366 | D33: =+B33+C33 -> 311366
A34: Total current assets | B34: =SUM(B27:B33) -> 209484831 | C34: =SUM(C27:C33) -> 0 | D34: =SUM(D27:D33) -> 209484831
A36: Total assets | B36: =B23+B34 -> 280843423 | C36: =C23+C34 -> 0 | D36: =D23+D34 -> 280843423
A38: Equity and Liabilities
A39: Equity
A40: Equity share capital | B40: =ROUND(100000/Master!$B$23,0) -> 100000 | D40: =+B40+C40 -> 100000
A41: Other equity | B41: =ROUND(81440201/Master!$B$23,0) -> 81440201 | C41: =-C100 -> 0 | D41: =+B41+C41 -> 81440201
A42: Total equity | B42: =SUM(B40:B41) -> 81540201 | C42: =SUM(C40:C41) -> 0 | D42: =SUM(D40:D41) -> 81540201
A44: Liabilities
A45: Non current liabilities
A46: Financial liabilities
A47: Preference shares | B47: =ROUND(187488357/Master!$B$23,0) -> 187488357 | D47: =+B47+C47 -> 187488357
A48: Trade payables | B48: =ROUND(0/Master!$B$23,0) -> 0 | D48: =+B48+C48 -> 0
...

Sheet BS
A3: Balance Sheet as at 31 March 2025
A4: (Amounts are stated in ₹ Lakhs unless otherwise stated)
G6: As at | I6: As at
A7: Particular | C7: Notes | G7: 45747 | I7: 45382
A9: Assets
A10: Non current assets | Y10: 24.08.2021 version | Z10: Difference
A11: Property and equipment | C11: ='3-4'!A7 -> 3 | E11: =ROUND(G11/10^5,0) -> 0 | G11: ='Sch - BS'!G9 -> -1 | I11: ='Sch - BS'!I9 -> -1 | J11: =+G11-I11 -> 0 | L11: =+J11+K11 -> 0 | Q11: =ROUND(G11,0) -> -1 | W11: =+G11-I11 -> 0 | X11: =+G11-W11 -> -1 | Y11: 0 | Z11: =+G11-Y11 -> -1
A12: Capital work-in-progress | C12: ='3-4'!A7 -> 3 | E12: =ROUND(G12/10^5,0) -> 0 | G12: ='Sch - BS'!G11 -> 0 | I12: ='Sch - BS'!I11 -> 0 | J12: =+G12-I12 -> 0 | L12: =+J12-K12 -> 0 | Q12: =ROUND(G12,0) -> 0 | W12: 0 | X12: =+G12-W12 -> 0 | Y12: 0 | Z12: =+G12-Y12 -> 0
A13: Intangible assets | C13: ='3-4'!A7 -> 3 | E13: =ROUND(G13/10^5,0) -> 0 | G13: ='Sch - BS'!G10 -> 0 | I13: ='Sch - BS'!I10 -> 0 | J13: =+G13-I13 -> 0 | L13: =+J13-K13 -> 0 | Q13: =ROUND(G13,0) -> 0 | W13: 0 | X13: =+G13-W13 -> 0 | Y13: 0 | Z13: =+G13-Y13 -> 0
A14: Right-of-use asset | C14: =+'3-4'!A47 -> 3A | E14: =ROUND(G14/10^5,0) -> 32 | G14: ='3-4'!J69 -> 3218600.4 | I14: ='3-4'!J70 -> 6258296 | J14: =+G14-I14 -> -3039695.6 | K14: =+CF!F13 -> 3206674 | L14: =+J14+K14 -> 166978.4 | Q14: =ROUND(G14,0) -> 3218600 | S14: 3218601 | T14: =G14-S14 -> -0.6 | W14: =+G14-I14 -> -3039695.6 | X14: =+G14-W14 -> 6258296 | Y14: 158 | Z14: =+G14-Y14 -> 3218442.4 | AA14: =+G14+PL!F17-827641 -> 5597633.4
A15: Financial assets | E15: =ROUND(G15/10^5,0) -> 0 | L15: =+J15+K15 -> 0 | Q15: =ROUND(G15,0) -> 0 | X15: =+G15-W15 -> 0 | Z15: =+G15-Y15 -> 0 | AA15: =+W48+W60 -> -3415049
A16: Investments | E16: =ROUND(G16/10^5,0) -> 0 | G16: ='Sch - BS'!G31 -> 0 | I16: ='Sch - BS'!I31 -> 0 | L16: =+J16-K16 -> 0 | Q16: =ROUND(G16,0) -> 0 | W16: 0 | X16: =+G16-W16 -> 0 | Y16: 0 | Z16: =+G16-Y16 -> 0
A17: Loans | E17: =ROUND(G17/10^5,0) -> 0 | G17: ='Sch - BS'!G35 -> 0 | I17: ='Sch - BS'!I35 -> 0 | L17: =+J17-K17 -> 0 | Q17: =ROUND(G17,0) -> 0 | W17: 0 | X17: =+G17-W17 -> 0 | Y17: 0 | Z17: =+G17-Y17 -> 0
A18: Other financial assets | C18: ='3-4'!A74 -> 4 | E18: =ROUND(G18/10^5,0) -> 0 | G18: ='Sch - BS'!G47 -> 0 | I18: ='Sch - BS'!I47 -> 2602786 | J18: =+G18-I18 -> -2602786 | L18: =+J18+K18 -> -2602786 | Q18: =ROUND(G18,0) -> 0 | W18: =+G18-I18 -> -2602786 | X18: =+G18-W18 -> 2602786 | Y18: 0 | Z18: =+G18-Y18 -> 0 | AA18: =+AA14-AA15 -> 9012682.4
A19: Deferred tax assets (net) | C19: =+'5-9'!A7*0+'10-17'!A232 -> 14 | E19: =ROUND(G19/10^5,0) -> 33 | G19: =-'Sch - BS'!G53 -> 3328863 | I19: =-'Sch - BS'!I53 -> 6767874 | L19: =+J19-K19 -> 0 | Q19: =ROUND(G19,0) -> 3328863 | W19: 0 | X19: =+G19-W19 -> 3328863 | Y19: 0 | Z19: =+G19-Y19 -> 3328863
A20: Other non-current assets | C20: ='5-9'!A40 -> 5 | E20: =ROUND(G20/10^5,0) -> 113 | G20: ='Sch - BS'!G76 -> 11303080 | I20: ='Sch - BS'!I76 -> 11303080 | J20: =+G20-I20 -> 0 | L20: =+J20+K20 -> 0 | Q20: =ROUND(G20,0) -> 11303080 | W20: =+G20-I20 -> 0 | X20: =+G20-W20 -> 11303080 | Y20: 113 | Z20: =+G20-Y20 -> 11302967
A21: Income tax assets (net) | C21: =+'18-26'!A189 -> 25 | E21: =ROUND(G21/10^5,0) -> -8 | G21: ='Sch - BS'!G82 -> -839640 | I21: ='Sch - BS'!I82 -> 40668266 | J21: =+G21-I21 -> -41507906 | K21: =+CF!F45 -> -1105803 | L21: =+J21+K21 -> -42613709 | O21: 42020656 | P21: =O21-I21 -> 1352390 | Q21: =ROUND(G21,0) -> -839640 | W21: =+G21-I21 -> -41507906 | X21: =+G21-W21 -> 40668266 | Y21: 418 | Z21: =+G21-Y21 -> -840058
A22: Total non-current assets | E22: =SUM(E11:E21) -> 170 | G22: =SUM(G11:G21) -> 17010902 | I22: =SUM(I11:I21) -> 67600301 | Q22: =SUM(Q11:Q21) -> 17010902 | W22: =+G22-I22 -> -50589399 | X22: =+G22-W22 -> 67600301 | Y22: 689 | Z22: =+G22-Y22 -> 17010213
X23: =+G23-W23 -> 0 | Z23: =+G23-Y23 -> 0
A24: Current assets | X24: =+G24-W24 -> 0 | Z24: =+G24-Y24 -> 0
A25: Financial assets | X25: =+G25-W25 -> 0 | Z25: =+G25-Y25 -> 0
A26: Investments | C26: ='5-9'!A62 -> 6 | E26: =G26/10^5 -> -0.0001 | G26: ='Sch - BS'!G96 -> -10 | I26: ='Sch - BS'!I96 -> -10 | Q26: 0 | W26: 0 | X26: =+G26-W26 -> -10 | Y26: 0 | Z26: =+G26-Y26 -> -10
A27: Trade receivables | C27: ='5-9'!A84 -> 6 | E27: =ROUND(G27/10^5,0) -> 86 | G27: ='Sch - BS'!G114+0.12 -> 8607499.1 | I27: ='Sch - BS'!I114 -> 2012487 | J27: =+G27-I27 -> 6595012.1 | K27: =CF!F36 -> -6693443.1 | L27: =+J27+K27 -> -98431 | M27: 75 | N27: =I27-M27 -> 2012412 | Q27: =ROUND(G27,0) -> 8607499 | T27: =G27-I27 -> 6595012.1 | W27: =+G27-I27 -> 6595012.1 | X27: =+G27-W27 -> 2012487 | Y27: 25 | Z27: =+G27-Y27 -> 8607474.1
A28: Cash and cash equivalents | C28: =+'5-9'!A127 -> 7 | E28: =ROUND(G28/10^5,0) -> 2437 | G28: ='Sch - BS'!G122 -> 243659518 | I28: ='Sch - BS'!I122 -> 243805184 | J28: =+G28-I28 -> -145666 | L28: =+J28+K28 -> -145666 | M28: 2218 | N28: =I28-M28 -> 243802966 | Q28: =ROUND(G28,0) -> 243659518 | W28: =+G28-I28 -> -145666 | X28: =+G28-W28 -> 243805184 | Y28: 2193 | Z28: =+G28-Y28 -> 243657325
A29: Bank balances | E29: =ROUND(G29/10^5,0) -> 0 | G29: ='Sch - BS'!G128*0 -> 0 | I29: ='Sch - BS'!I128*0 -> 0 | J29: =+G29-I29 -> 0 | L29: =+J29-K29 -> 0 | Q29: =ROUND(G29,0) -> 0 | W29: =+G29-I29 -> 0 | X29: =+G29-W29 -> 0 | Y29: 0 | Z29: =+G29-Y29 -> 0
A30: Loans | E30: =ROUND(G30/10^5,0) -> 0 | G30: ='Sch - BS'!G132 -> 0 | I30: ='Sch - BS'!I132 -> 0 | J30: =+G30-I30 -> 0 | L30: =+J30-K30 -> 0 | Q30: =ROUND(G30,0) -> 0 | W30: =+G30-I30 -> 0 | X30: =+G30-W30 -> 0 | Y30: 0 | Z30: =+G30-Y30 -> 0
A31: Other financial assets | C31: ='5-9'!A162 -> 8 | E31: =ROUND(G31/10^5,0) -> 55 | G31: ='Sch - BS'!G148 -> 5526491 | I31: ='Sch - BS'!I148 -> 2678928 | J31: =+G31-I31 -> 2847563 | K31: =+CF!F37 -> 182600 | L31: =+J31+K31 -> 3030163 | M31: 20 | N31: =I31-M31 -> 2678908 | Q31: =ROUND(G31,0) -> 5526491 | W31: =+G31-I31 -> 2847563 | X31: =+G31-W31 -> 2678928 | Y31: 32 | Z31: =+G31-Y31 -> 5526459
A32: Other current assets | C32: =+'5-9'!A196 -> 9 | E32: =ROUND(G32/10^5,0) -> 5 | G32: ='Sch - BS'!G169 -> 506907 | I32: ='Sch - BS'!I169 -> 345410 | J32: =+G32-I32 -> 161497 | K32: =+CF!F38 -> -161497 | L32: =+J32+K32 -> 0 | M32: 1 | N32: =I32-M32 -> 345409 | Q32: =ROUND(G32,0) -> 506907 | W32: =+G32-I32 -> 161497 | X32: =+G32-W32 -> 345410 | Y32: 1 | Z32: =+G32-Y32 -> 506906
A33: Income tax assets (net) | C33: =+'18-26'!A189 -> 25 | E33: =G33/10^5 -> 0 | G33: =ROUND('BS Gr'!H522/Master!$B$23,0) -> 0 | I33: =ROUND('BS Gr'!L522/Master!$B$23,0) -> 0 | Q33: =ROUND(G33,0) -> 0 | W33: =+G33-I33 -> 0 | X33: =+G33-W33 -> 0 | Y33: 0 | Z33: =+G33-Y33 -> 0
A34: Total current assets | E34: =SUM(E26:E33) -> 2582.9999 | G34: =SUM(G26:G33) -> 2.5830041e+08 | I34: =SUM(I26:I33) -> 248841999 | Q34: =SUM(Q26:Q33) -> 258300415 | W34: =+G34-I34 -> 9458406.1 | X34: =+G34-W34 -> 248841999 | Y34: 2251 | Z34: =+G34-Y34 -> 2.5829815e+08
X35: =+G35-W35 -> 0 | Z35: =+G35-Y35 -> 0
A36: Total assets | E36: =E22+E34 -> 2752.9999 | G36: =G22+G34 -> 2.7531131e+08 | I36: =I22+I34 -> 316442300 | Q36: =Q22+Q34 -> 275311317 | W36: =+G36-I36 -> -41130992 | X36: =+G36-W36 -> 316442300 | Y36: 2940 | Z36: =+G36-Y36 -> 2.7530837e+08
J37: =G31-G20 -> -5776589 | X37: =+G37-W37 -> 0 | Z37: =+G37-Y37 -> 0
A38: Equity and Liabilities | X38: =+G38-W38 -> 0 | Z38: =+G38-Y38 -> 0
A39: Equity | X39: =+G39-W39 -> 0 | Z39: =+G39-Y39 -> 0
A40: Share capital | C40: ='10-17'!A8 -> 10 | E40: =ROUND(G40/10^5,0) -> 1 | G40: ='Sch - BS'!G181 -> 100000 | I40: ='Sch - BS'!I181 -> 100000 | J40: =+G40-I40 -> 0 | L40: =+J40-K40 -> 0 | Q40: =ROUND(G40,0) -> 100000 | W40: =+G40-I40 -> 0 | X40: =+G40-W40 -> 100000 | Y40: 1 | Z40: =+G40-Y40 -> 99999
A41: Other equity | E41: =ROUND(G41/10^5,0) -> 170 | G41: ='Sch - BS'!G226 -> 17022765 | I41: ='Sch - BS'!I226-75824 -> 66078334 | J41: =+G41-I41 -> -49055569 | L41: =+J41-K41 -> -49055569 | Q41: =ROUND(G41,0) -> 17022765 | W41: =+G41-I41 -> -49055569 | X41: =+G41-W41 -> 66078334 | Y41: 482 | Z41: =+G41-Y41 -> 17022283
A42: Total equity | E42: =SUM(E40:E41) -> 171 | G42: =SUM(G40:G41) -> 17122765 | I42: =SUM(I40:I41) -> 66178334 | Q42: =SUM(Q40:Q41) -> 17122765 | W42: =+G42-I42 -> -49055569 | X42: =+G42-W42 -> 66178334 | Y42: 483 | Z42: =+G42-Y42 -> 17122282
W43: =+PL!F48 -> -49055769 | X43: =+G43-W43 -> 49055769 | Z43: =+G43-Y43 -> 0
A44: Liabilities | W44: =+W42-W43 -> 200 | X44: =+G44-W44 -> -200 | Z44: =+G44-Y44 -> 0
...

Sheet Sheet1

Sheet BS Gr
A1: =+Master!B2 -> Syntel Solutions (India) Private Limited | D1: Ind AS account codes
A2: ="Balance sheet Grouping as at " &Master!$B$5 -> Balance sheet Grouping as at 31st March 2025 | H2: ="Current and Non Current as at " &Master!$B$5 -> Current and Non Current as at 31st March 2025 | L2: ="Current and Non Current as at " &Master!$B$11 -> Current and Non Current as at 30th March 2024
A4: GL Code | B4: Account description | D4: As at | F4: As at | H4: Current | I4: Non Current | J4: Difference | L4: Current | M4: Non Current | N4: Difference | U4: Nature of | AC4: Balance as per 31 Mar 23 IFRS TB | AE4: Remarks
D5: =Master!B4 -> 45747 | F5: =Master!B10 -> 45381 | U5: Balance | W5: BS Gr_Current | X5: BS Gr_Non Current | Z5: Main Head | AA5: BS Gr_Current | AB5: BS Gr_Non Current | AD5: Difference | AE5: Remarks | AQ5: Assets | AR5: Liability
A7: 100000 | B7: =VLOOKUP(A7,'TB for financial'!A:B,2,0) -> TDR reclassed > 3 months | D7: =VLOOKUP(A7,'TB for financial'!A:F,6,0) -> 0 | F7: =VLOOKUP(A7,'TB for financial'!A:K,10,0) -> 0 | H7: =D7-I7 -> 0 | I7: 0 | J7: =+D7-H7-I7 -> 0 | L7: =F7-M7 -> 0 | M7: 0 | N7: =+F7-L7-M7 -> 0 | U7: Cur | W7: Current investments | Y7: Current Assets | Z7: Financial Assets | AA7: Investments | AC7: 0 | AD7: =+D7-AC7 -> 0 | AF7: 100000
A8: 100518 | B8: =VLOOKUP(A8,'TB for financial'!A:B,2,0) -> Taurus Mutual Fund | D8: =VLOOKUP(A8,'TB for financial'!A:F,6,0) -> 0 | F8: =VLOOKUP(A8,'TB for financial'!A:K,11,0) -> 0 | H8: =D8-I8 -> 0 | I8: 0 | J8: =+D8-H8-I8 -> 0 | L8: =F8-M8 -> 0 | M8: 0 | N8: =+F8-L8-M8 -> 0 | U8: Cur | W8: Current investments | Y8: Current Assets | Z8: Financial Assets | AA8: Investments | AC8: 0 | AD8: =+D8-AC8 -> 0 | AF8: 100518
A9: 100529 | B9: =VLOOKUP(A9,'TB for financial'!A:B,2,0) -> Reliance Floating Rate Fund | D9: =VLOOKUP(A9,'TB for financial'!A:F,6,0) -> 0 | F9: =VLOOKUP(A9,'TB for financial'!A:K,11,0) -> 0 | H9: =D9-I9 -> 0 | I9: 0 | J9: =+D9-H9-I9 -> 0 | L9: =F9-M9 -> 0 | M9: 0 | N9: =+F9-L9-M9 -> 0 | U9: Cur | W9: Current investments | Y9: Current Assets | Z9: Financial Assets | AA9: Investments | AC9: 0 | AD9: =+D9-AC9 -> 0 | AF9: 100529
A10: 100543 | B10: =VLOOKUP(A10,'TB for financial'!A:B,2,0) -> Axis Mutual Fund | D10: =VLOOKUP(A10,'TB for financial'!A:F,6,0) -> 0 | F10: =VLOOKUP(A10,'TB for financial'!A:K,11,0) -> 0 | H10: =D10-I10 -> 0 | I10: 0 | J10: =+D10-H10-I10 -> 0 | L10: =F10-M10 -> 0 | M10: 0 | N10: =+F10-L10-M10 -> 0 | U10: Cur | W10: Current investments | Y10: Current Assets | Z10: Financial Assets | AA10: Investments | AC10: 0 | AD10: =+D10-AC10 -> 0 | AF10: 100543
A11: 100544 | B11: =VLOOKUP(A11,'TB for financial'!A:B,2,0) -> IDBI Mutual Fund | D11: =VLOOKUP(A11,'TB for financial'!A:F,6,0) -> 0 | F11: =VLOOKUP(A11,'TB for financial'!A:K,11,0) -> 0 | H11: =D11-I11 -> 0 | I11: 0 | J11: =+D11-H11-I11 -> 0 | L11: =F11-M11 -> 0 | M11: 0 | N11: =+F11-L11-M11 -> 0 | U11: Cur | W11: Current investments | Y11: Current Assets | Z11: Financial Assets | AA11: Investments | AC11: 0 | AD11: =+D11-AC11 -> 0 | AF11: 100544
A12: 100547 | B12: =VLOOKUP(A12,'TB for financial'!A:B,2,0) -> Peerlees Mutual Fund | D12: =VLOOKUP(A12,'TB for financial'!A:F,6,0) -> 0.0099999998 | F12: =VLOOKUP(A12,'TB for financial'!A:K,11,0) -> 0.0099999998 | H12: =D12-I12 -> 0.0099999998 | I12: 0 | J12: =+D12-H12-I12 -> 0 | L12: =F12-M12 -> 0.0099999998 | M12: 0 | N12: =+F12-L12-M12 -> 0 | U12: Cur | W12: Current investments | Y12: Current Assets | Z12: Financial Assets | AA12: Investments | AC12: 0 | AD12: =+D12-AC12 -> 0.0099999998 | AF12: 100547 | AQ12: =D12 -> 0.0099999998
A13: 100548 | B13: =VLOOKUP(A13,'TB for financial'!A:B,2,0) -> L & T Mutual Fund | D13: =VLOOKUP(A13,'TB for financial'!A:F,6,0) -> 0 | F13: =VLOOKUP(A13,'TB for financial'!A:K,11,0) -> 0 | H13: =D13-I13 -> 0 | I13: 0 | J13: =+D13-H13-I13 -> 0 | L13: =F13-M13 -> 0 | M13: 0 | N13: =+F13-L13-M13 -> 0 | U13: Cur | W13: Current investments | Y13: Current Assets | Z13: Financial Assets | AA13: Investments | AC13: 0 | AD13: =+D13-AC13 -> 0 | AF13: 100548
A14: 100549 | B14: =VLOOKUP(A14,'TB for financial'!A:B,2,0) -> Canara Robeco Mutual Fund | D14: =VLOOKUP(A14,'TB for financial'!A:F,6,0) -> 0 | F14: =VLOOKUP(A14,'TB for financial'!A:K,11,0) -> 0 | H14: =D14-I14 -> 0 | I14: 0 | J14: =+D14-H14-I14 -> 0 | L14: =F14-M14 -> 0 | M14: 0 | N14: =+F14-L14-M14 -> 0 | U14: Cur | W14: Current investments | Y14: Current Assets | Z14: Financial Assets | AA14: Investments | AC14: 0 | AD14: =+D14-AC14 -> 0 | AF14: 100549
A15: 100550 | B15: =VLOOKUP(A15,'TB for financial'!A:B,2,0) -> Baroda Pioneer Mutual Fund | D15: =VLOOKUP(A15,'TB for financial'!A:F,6,0) -> -1.18 | F15: =VLOOKUP(A15,'TB for financial'!A:K,11,0) -> -1.18 | H15: =D15-I15 -> -1.18 | I15: 0 | J15: =+D15-H15-I15 -> 0 | L15: =F15-M15 -> -1.18 | M15: 0 | N15: =+F15-L15-M15 -> 0 | U15: Cur | W15: Current investments | Y15: Current Assets | Z15: Financial Assets | AA15: Investments | AC15: 0 | AD15: =+D15-AC15 -> -1.18 | AF15: 100550 | AQ15: =D15 -> -1.18
A16: 100551 | B16: =VLOOKUP(A16,'TB for financial'!A:B,2,0) -> HDFC High Int. Fund - Reg. Gr | D16: =VLOOKUP(A16,'TB for financial'!A:F,6,0) -> 0 | F16: =VLOOKUP(A16,'TB for financial'!A:K,11,0) -> 0 | H16: =D16-I16 -> 0 | I16: 0 | J16: =+D16-H16-I16 -> 0 | L16: =F16-M16 -> 0 | M16: 0 | N16: =+F16-L16-M16 -> 0 | U16: Cur | W16: Current investments | Y16: Current Assets | Z16: Financial Assets | AA16: Investments | AC16: 0 | AD16: =+D16-AC16 -> 0 | AF16: 100551
A17: 100552 | B17: =VLOOKUP(A17,'TB for financial'!A:B,2,0) -> Templeton India Inc. Fund - Gr | D17: =VLOOKUP(A17,'TB for financial'!A:F,6,0) -> 0 | F17: =VLOOKUP(A17,'TB for financial'!A:K,11,0) -> 0 | H17: =D17-I17 -> 0 | I17: 0 | J17: =+D17-H17-I17 -> 0 | L17: =F17-M17 -> 0 | M17: 0 | N17: =+F17-L17-M17 -> 0 | U17: Cur | W17: Current investments | Y17: Current Assets | Z17: Financial Assets | AA17: Investments | AC17: 0 | AD17: =+D17-AC17 -> 0 | AF17: 100552
A18: 100553 | B18: =VLOOKUP(A18,'TB for financial'!A:B,2,0) -> Templeton Floating Fund - ST | D18: =VLOOKUP(A18,'TB for financial'!A:F,6,0) -> 0 | F18: =VLOOKUP(A18,'TB for financial'!A:K,11,0) -> 0 | H18: =D18-I18 -> 0 | I18: 0 | J18: =+D18-H18-I18 -> 0 | L18: =F18-M18 -> 0 | M18: 0 | N18: =+F18-L18-M18 -> 0 | U18: Cur | W18: Current investments | Y18: Current Assets | Z18: Financial Assets | AA18: Investments | AC18: 0 | AD18: =+D18-AC18 -> 0 | AF18: 100553
A19: 100554 | B19: =VLOOKUP(A19,'TB for financial'!A:B,2,0) -> DSP ML - Bond Fund - Gr. | D19: =VLOOKUP(A19,'TB for financial'!A:F,6,0) -> 0 | F19: =VLOOKUP(A19,'TB for financial'!A:K,11,0) -> 0 | H19: =D19-I19 -> 0 | I19: 0 | J19: =+D19-H19-I19 -> 0 | L19: =F19-M19 -> 0 | M19: 0 | N19: =+F19-L19-M19 -> 0 | U19: Cur | W19: Current investments | Y19: Current Assets | Z19: Financial Assets | AA19: Investments | AC19: 0 | AD19: =+D19-AC19 -> 0 | AF19: 100554
A20: 100555 | B20: =VLOOKUP(A20,'TB for financial'!A:B,2,0) -> DSP ML Liquidity Fund - Gr | D20: =VLOOKUP(A20,'TB for financial'!A:F,6,0) -> 0 | F20: =VLOOKUP(A20,'TB for financial'!A:K,11,0) -> 0 | H20: =D20-I20 -> 0 | I20: 0 | J20: =+D20-H20-I20 -> 0 | L20: =F20-M20 -> 0 | M20: 0 | N20: =+F20-L20-M20 -> 0 | U20: Cur | W20: Current investments | Y20: Current Assets | Z20: Financial Assets | AA20: Investments | AC20: 0 | AD20: =+D20-AC20 -> 0 | AF20: 100555
A21: 100556 | B21: =VLOOKUP(A21,'TB for financial'!A:B,2,0) -> DSP ML Floating Fund - Gr | D21: =VLOOKUP(A21,'TB for financial'!A:F,6,0) -> 1.25 | F21: =VLOOKUP(A21,'TB for financial'!A:K,11,0) -> 1.25 | H21: =D21-I21 -> 1.25 | I21: 0 | J21: =+D21-H21-I21 -> 0 | L21: =F21-M21 -> 1.25 | M21: 0 | N21: =+F21-L21-M21 -> 0 | U21: Cur | W21: Current investments | Y21: Current Assets | Z21: Financial Assets | AA21: Investments | AC21: 0 | AD21: =+D21-AC21 -> 1.25 | AF21: 100556 | AQ21: =D21 -> 1.25
A22: 100557 | B22: =VLOOKUP(A22,'TB for financial'!A:B,2,0) -> Prudential ICICI Floating - Gr | D22: =VLOOKUP(A22,'TB for financial'!A:F,6,0) -> 0 | F22: =VLOOKUP(A22,'TB for financial'!A:K,11,0) -> 0 | H22: =D22-I22 -> 0 | I22: 0 | J22: =+D22-H22-I22 -> 0 | L22: =F22-M22 -> 0 | M22: 0 | N22: =+F22-L22-M22 -> 0 | U22: Cur | W22: Current investments | Y22: Current Assets | Z22: Financial Assets | AA22: Investments | AC22: 0 | AD22: =+D22-AC22 -> 0 | AF22: 100557
A23: 100558 | B23: =VLOOKUP(A23,'TB for financial'!A:B,2,0) -> Grindlays Cash Fund - IP - Gr | D23: =VLOOKUP(A23,'TB for financial'!A:F,6,0) -> 0 | F23: =VLOOKUP(A23,'TB for financial'!A:K,11,0) -> 0 | H23: =D23-I23 -> 0 | I23: 0 | J23: =+D23-H23-I23 -> 0 | L23: =F23-M23 -> 0 | M23: 0 | N23: =+F23-L23-M23 -> 0 | U23: Cur | W23: Current investments | Y23: Current Assets | Z23: Financial Assets | AA23: Investments | AC23: 0 | AD23: =+D23-AC23 -> 0 | AF23: 100558
A24: 100559 | B24: =VLOOKUP(A24,'TB for financial'!A:B,2,0) -> HSBC Cash Fund - Growth | D24: =VLOOKUP(A24,'TB for financial'!A:F,6,0) -> 0 | F24: =VLOOKUP(A24,'TB for financial'!A:K,11,0) -> 0 | H24: =D24-I24 -> 0 | I24: 0 | J24: =+D24-H24-I24 -> 0 | L24: =F24-M24 -> 0 | M24: 0 | N24: =+F24-L24-M24 -> 0 | U24: Cur | W24: Current investments | Y24: Current Assets | Z24: Financial Assets | AA24: Investments | AC24: 0 | AD24: =+D24-AC24 -> 0 | AF24: 100559
A25: 100560 | B25: =VLOOKUP(A25,'TB for financial'!A:B,2,0) -> Reliance Treasury - IP - Gr | D25: =VLOOKUP(A25,'TB for financial'!A:F,6,0) -> 0 | F25: =VLOOKUP(A25,'TB for financial'!A:K,11,0) -> 0 | H25: =D25-I25 -> 0 | I25: 0 | J25: =+D25-H25-I25 -> 0 | L25: =F25-M25 -> 0 | M25: 0 | N25: =+F25-L25-M25 -> 0 | U25: Cur | W25: Current investments | Y25: Current Assets | Z25: Financial Assets | AA25: Investments | AC25: 0 | AD25: =+D25-AC25 -> 0 | AF25: 100560
A26: 100561 | B26: =VLOOKUP(A26,'TB for financial'!A:B,2,0) -> Reliance STerm Fund - Gr | D26: =VLOOKUP(A26,'TB for financial'!A:F,6,0) -> 0 | F26: =VLOOKUP(A26,'TB for financial'!A:K,11,0) -> 0 | H26: =D26-I26 -> 0 | I26: 0 | J26: =+D26-H26-I26 -> 0 | L26: =F26-M26 -> 0 | M26: 0 | N26: =+F26-L26-M26 -> 0 | U26: Cur | W26: Current investments | Y26: Current Assets | Z26: Financial Assets | AA26: Investments | AC26: 0 | AD26: =+D26-AC26 -> 0 | AF26: 100561
A27: 100562 | B27: =VLOOKUP(A27,'TB for financial'!A:B,2,0) -> TLHG TATA Liquid HIF - Gr | D27: =VLOOKUP(A27,'TB for financial'!A:F,6,0) -> -1.2 | F27: =VLOOKUP(A27,'TB for financial'!A:K,11,0) -> -1.2 | H27: =D27-I27 -> -1.2 | I27: 0 | J27: =+D27-H27-I27 -> 0 | L27: =F27-M27 -> -1.2 | M27: 0 | N27: =+F27-L27-M27 -> 0 | U27: Cur | W27: Current investments | Y27: Current Assets | Z27: Financial Assets | AA27: Investments | AC27: 0 | AD27: =+D27-AC27 -> -1.2 | AF27: 100562 | AQ27: =D27 -> -1.2
A28: 100563 | B28: =VLOOKUP(A28,'TB for financial'!A:B,2,0) -> Kotak Liquid IP - Growth | D28: =VLOOKUP(A28,'TB for financial'!A:F,6,0) -> -0.080000015 | F28: =VLOOKUP(A28,'TB for financial'!A:K,11,0) -> -0.080000015 | H28: =D28-I28 -> -0.080000015 | I28: 0 | J28: =+D28-H28-I28 -> 0 | L28: =F28-M28 -> -0.080000015 | M28: 0 | N28: =+F28-L28-M28 -> 0 | U28: Cur | W28: Current investments | Y28: Current Assets | Z28: Financial Assets | AA28: Investments | AC28: 0 | AD28: =+D28-AC28 -> -0.080000015 | AF28: 100563 | AQ28: =D28 -> -0.080000015
A29: 100564 | B29: =VLOOKUP(A29,'TB for financial'!A:B,2,0) -> Principal Cash Mgmt Fund | D29: =VLOOKUP(A29,'TB for financial'!A:F,6,0) -> 0 | F29: =VLOOKUP(A29,'TB for financial'!A:K,11,0) -> 0 | H29: =D29-I29 -> 0 | I29: 0 | J29: =+D29-H29-I29 -> 0 | L29: =F29-M29 -> 0 | M29: 0 | N29: =+F29-L29-M29 -> 0 | U29: Cur | W29: Current investments | Y29: Current Assets | Z29: Financial Assets | AA29: Investments | AC29: 0 | AD29: =+D29-AC29 -> 0 | AF29: 100564
A30: 100565 | B30: =VLOOKUP(A30,'TB for financial'!A:B,2,0) -> JM Short Term Fund - IP | D30: =VLOOKUP(A30,'TB for financial'!A:F,6,0) -> 0 | F30: =VLOOKUP(A30,'TB for financial'!A:K,11,0) -> 0 | H30: =D30-I30 -> 0 | I30: 0 | J30: =+D30-H30-I30 -> 0 | L30: =F30-M30 -> 0 | M30: 0 | N30: =+F30-L30-M30 -> 0 | U30: Cur | W30: Current investments | Y30: Current Assets | Z30: Financial Assets | AA30: Investments | AC30: 0 | AD30: =+D30-AC30 -> 0 | AF30: 100565
A31: 100566 | B31: =VLOOKUP(A31,'TB for financial'!A:B,2,0) -> Birla Bond Plus IP - Gr | D31: =VLOOKUP(A31,'TB for financial'!A:F,6,0) -> 0 | F31: =VLOOKUP(A31,'TB for financial'!A:K,11,0) -> 0 | H31: =D31-I31 -> 0 | I31: 0 | J31: =+D31-H31-I31 -> 0 | L31: =F31-M31 -> 0 | M31: 0 | N31: =+F31-L31-M31 -> 0 | U31: Cur | W31: Current investments | Y31: Current Assets | Z31: Financial Assets | AA31: Investments | AC31: 0 | AD31: =+D31-AC31 -> 0 | AF31: 100566
A32: 100567 | B32: =VLOOKUP(A32,'TB for financial'!A:B,2,0) -> Birla Cash Plus - IP - Gr | D32: =VLOOKUP(A32,'TB for financial'!A:F,6,0) -> 0.13 | F32: =VLOOKUP(A32,'TB for financial'!A:K,11,0) -> 0.13 | H32: =D32-I32 -> 0.13 | I32: 0 | J32: =+D32-H32-I32 -> 0 | L32: =F32-M32 -> 0.13 | M32: 0 | N32: =+F32-L32-M32 -> 0 | U32: Cur | W32: Current investments | Y32: Current Assets | Z32: Financial Assets | AA32: Investments | AC32: 0 | AD32: =+D32-AC32 -> 0.13 | AF32: 100567 | AQ32: =D32 -> 0.13
A33: 100568 | B33: =VLOOKUP(A33,'TB for financial'!A:B,2,0) -> DSP ML ST Fund - Gr | D33: =VLOOKUP(A33,'TB for financial'!A:F,6,0) -> 0 | F33: =VLOOKUP(A33,'TB for financial'!A:K,11,0) -> 0 | H33: =D33-I33 -> 0 | I33: 0 | J33: =+D33-H33-I33 -> 0 | L33: =F33-M33 -> 0 | M33: 0 | N33: =+F33-L33-M33 -> 0 | U33: Cur | W33: Current investments | Y33: Current Assets | Z33: Financial Assets | AA33: Investments | AC33: 0 | AD33: =+D33-AC33 -> 0 | AF33: 100568
A34: 100569 | B34: =VLOOKUP(A34,'TB for financial'!A:B,2,0) -> Kotak KMMF - K Floater | D34: =VLOOKUP(A34,'TB for financial'!A:F,6,0) -> 0 | F34: =VLOOKUP(A34,'TB for financial'!A:K,11,0) -> 0 | H34: =D34-I34 -> 0 | I34: 0 | J34: =+D34-H34-I34 -> 0 | L34: =F34-M34 -> 0 | M34: 0 | N34: =+F34-L34-M34 -> 0 | U34: Cur | W34: Current investments | Y34: Current Assets | Z34: Financial Assets | AA34: Investments | AC34: 0 | AD34: =+D34-AC34 -> 0 | AF34: 100569
A35: 100570 | B35: =VLOOKUP(A35,'TB for financial'!A:B,2,0) -> Grindlays Floating Rate Fund - IP - Gr | D35: =VLOOKUP(A35,'TB for financial'!A:F,6,0) -> 0 | F35: =VLOOKUP(A35,'TB for financial'!A:K,11,0) -> 0 | H35: =D35-I35 -> 0 | I35: 0 | J35: =+D35-H35-I35 -> 0 | L35: =F35-M35 -> 0 | M35: 0 | N35: =+F35-L35-M35 -> 0 | U35: Cur | W35: Current investments | Y35: Current Assets | Z35: Financial Assets | AA35: Investments | AC35: 0 | AD35: =+D35-AC35 -> 0 | AF35: 100570
A36: 100571 | B36: =VLOOKUP(A36,'TB for financial'!A:B,2,0) -> Prudential ICICI Liquid - Gr | D36: =VLOOKUP(A36,'TB for financial'!A:F,6,0) -> -0.35 | F36: =VLOOKUP(A36,'TB for financial'!A:K,11,0) -> -0.35 | H36: =D36-I36 -> -0.35 | I36: 0 | J36: =+D36-H36-I36 -> 0 | L36: =F36-M36 -> -0.35 | M36: 0 | N36: =+F36-L36-M36 -> 0 | U36: Cur | W36: Current investments | Y36: Current Assets | Z36: Financial Assets | AA36: Investments | AC36: 0 | AD36: =+D36-AC36 -> -0.35 | AF36: 100571 | AQ36: =D36 -> -0.35
A37: 100572 | B37: =VLOOKUP(A37,'TB for financial'!A:B,2,0) -> Templeton India Tresury Management | D37: =VLOOKUP(A37,'TB for financial'!A:F,6,0) -> 0 | F37: =VLOOKUP(A37,'TB for financial'!A:K,11,0) -> 0 | H37: =D37-I37 -> 0 | I37: 0 | J37: =+D37-H37-I37 -> 0 | L37: =F37-M37 -> 0 | M37: 0 | N37: =+F37-L37-M37 -> 0 | U37: Cur | W37: Current investments | Y37: Current Assets | Z37: Financial Assets | AA37: Investments | AC37: 0 | AD37: =+D37-AC37 -> 0 | AF37: 100572
A38: 100573 | B38: =VLOOKUP(A38,'TB for financial'!A:B,2,0) -> HDFC Floating Rate Income Fund | D38: =VLOOKUP(A38,'TB for financial'!A:F,6,0) -> 0 | F38: =VLOOKUP(A38,'TB for financial'!A:K,11,0) -> 0 | H38: =D38-I38 -> 0 | I38: 0 | J38: =+D38-H38-I38 -> 0 | L38: =F38-M38 -> 0 | M38: 0 | N38: =+F38-L38-M38 -> 0 | U38: Cur | W38: Current investments | Y38: Current Assets | Z38: Financial Assets | AA38: Investments | AC38: 0 | AD38: =+D38-AC38 -> 0 | AF38: 100573
A39: 100574 | B39: =VLOOKUP(A39,'TB for financial'!A:B,2,0) -> Birla Floating Rate Fund | D39: =VLOOKUP(A39,'TB for financial'!A:F,6,0) -> 0 | F39: =VLOOKUP(A39,'TB for financial'!A:K,11,0) -> 0 | H39: =D39-I39 -> 0 | I39: 0 | J39: =+D39-H39-I39 -> 0 | L39: =F39-M39 -> 0 | M39: 0 | N39: =+F39-L39-M39 -> 0 | U39: Cur | W39: Current investments | Y39: Current Assets | Z39: Financial Assets | AA39: Investments | AC39: 0 | AD39: =+D39-AC39 -> 0 | AF39: 100574
A40: 100575 | B40: =VLOOKUP(A40,'TB for financial'!A:B,2,0) -> Deutsche Insta Cash Plus Fund | D40: =VLOOKUP(A40,'TB for financial'!A:F,6,0) -> 0 | F40: =VLOOKUP(A40,'TB for financial'!A:K,11,0) -> 0 | H40: =D40-I40 -> 0 | I40: 0 | J40: =+D40-H40-I40 -> 0 | L40: =F40-M40 -> 0 | M40: 0 | N40: =+F40-L40-M40 -> 0 | U40: Cur | W40: Current investments | Y40: Current Assets | Z40: Financial Assets | AA40: Investments | AC40: 0 | AD40: =+D40-AC40 -> 0 | AF40: 100575
A41: 100576 | B41: =VLOOKUP(A41,'TB for financial'!A:B,2,0) -> Templeton Floating Rate Income | D41: =VLOOKUP(A41,'TB for financial'!A:F,6,0) -> 0 | F41: =VLOOKUP(A41,'TB for financial'!A:K,11,0) -> 0 | H41: =D41-I41 -> 0 | I41: 0 | J41: =+D41-H41-I41 -> 0 | L41: =F41-M41 -> 0 | M41: 0 | N41: =+F41-L41-M41 -> 0 | U41: Cur | W41: Current investments | Y41: Current Assets | Z41: Financial Assets | AA41: Investments | AC41: 0 | AD41: =+D41-AC41 -> 0 | AF41: 100576
A42: 100577 | B42: =VLOOKUP(A42,'TB for financial'!A:B,2,0) -> Kotak Long Term Floater | D42: =VLOOKUP(A42,'TB for financial'!A:F,6,0) -> 0 | F42: =VLOOKUP(A42,'TB for financial'!A:K,11,0) -> 0 | H42: =D42-I42 -> 0 | I42: 0 | J42: =+D42-H42-I42 -> 0 | L42: =F42-M42 -> 0 | M42: 0 | N42: =+F42-L42-M42 -> 0 | U42: Cur | W42: Current investments | Y42: Current Assets | Z42: Financial Assets | AA42: Investments | AC42: 0 | AD42: =+D42-AC42 -> 0 | AF42: 100577
...

Sheet PL
A1: =+Master!B2 -> Syntel Solutions (India) Private Limited
A3: Statement of profit and loss for the year ended 31 March 2025
A4: =BS!A4 -> (Amounts are stated in ₹ Lakhs unless otherwise stated)
F6: Year ended | H6: Year ended
A7: Particular | D7: Notes | F7: =BS!G7 -> 45747 | H7: =BS!I7 -> 45382
A9: Revenue from operations
A10: - Software services | D10: ='18-26'!A8 -> 18 | E10: =ROUND(F10/10^5,0) -> 110 | F10: =+'Sch - PL'!E10+'Sch - PL'!E37 -> 10984519 | H10: =+'Sch - PL'!G10+'Sch - PL'!G37 -> 14480207 | T10: =+F10-H10 -> -3495688 | U10: =+F10-T10 -> 14480207 | X10: =H10-H15-H20 -> 146800
A11: Other income | D11: ='18-26'!A18 -> 19 | E11: =ROUND(F11/10^5,0) -> 159 | F11: =+'Sch - PL'!E41+'Sch - PL'!E18-'Sch - PL'!E37 -> 15903427 | H11: =+'Sch - PL'!G41+'Sch - PL'!G18-'Sch - PL'!G37 -> 36466002 | T11: =+F11-H11 -> -20562575 | U11: =+F11-T11 -> 36466002
A12: Total income | E12: =SUM(E10:E11) -> 269 | F12: =SUM(F10:F11) -> 26887946 | H12: =SUM(H10:H11) -> 50946209 | T12: =+F12-H12 -> -24058263 | W12: =H10-H15-H20 -> 146800
A14: Expenses
A15: Employee benefit expenses | D15: ='18-26'!A36 -> 20 | E15: =ROUND(F15/10^5,0) -> 71 | F15: =+'Sch - PL'!E53 -> 7068414 | H15: =+'Sch - PL'!G53 -> 8707022 | T15: =+F15-H15 -> -1638608 | U15: =+F15-T15 -> 8707022 | W15: =F10-F15-F20-F17 -> -7098846 | Y15: =H10-H15-H20 -> 146800
A16: Depreciation (#) | D16: ='3-4'!A7 -> 3 | E16: =ROUND(F16/10^5,0) -> 0 | F16: =ROUND('PL Gr'!E435/Master!$B$23,0) -> 0 | H16: =ROUND('PL Gr'!G435/Master!$B$23,0) -> 0 | T16: =+F16-H16 -> 0
A17: Depreciation and amortization | D17: ='3-4'!A47 -> 3A | E17: =ROUND(F17/10^5,0) -> 32 | F17: =ROUND('PL Gr'!E440/Master!$B$23,0) -> 3206674 | H17: =ROUND('PL Gr'!G440/Master!$B$23,0) -> 3180953 | T17: =+F17-H17 -> 25721 | U17: =+F17-T17 -> 3180953 | W17: =F10-F15-F17-F20 -> -7098846 | Y17: =H10-H15-H17-H20 -> -3034153
A18: Foreign travel expenses | D18: ='18-26'!A51 -> 21 | E18: =ROUND(F18/10^5,0) -> 0 | F18: =+'Sch - PL'!E72*0 -> 0 | H18: =+'Sch - PL'!G72*0 -> 0 | T18: =+F18-H18 -> 0
A19: Finance charges | D19: =+'18-26'!A65 -> 21 | E19: =ROUND(F19/10^5,0) -> 118 | F19: =ROUND(('PL Gr'!E377+'PL Gr'!E379+'PL Gr'!E452-'PL Gr'!E39+'PL Gr'!E400+'PL Gr'!E44)/Master!$B$23,0) -> 11760865 | H19: =ROUND(('PL Gr'!G377+'PL Gr'!G379+'PL Gr'!G452+'PL Gr'!G39+'PL Gr'!G400+'PL Gr'!G44)/Master!$B$23,0) -> 14031849 | T19: =+F19-H19 -> -2270984 | U19: =+F19-T19 -> 14031849
A20: Other expenses | D20: ='18-26'!A78 -> 22 | E20: =ROUND(F20/10^5,0) -> 78 | F20: =+'Sch - PL'!E108+'Sch - PL'!E72-'Sch - PL'!E18*0 -> 7808277 | H20: =+'Sch - PL'!G108+'Sch - PL'!G72-'Sch - PL'!G18*0-204068 -> 5626385 | T20: =+F20-H20 -> 2181892 | U20: =+F20-T20 -> 5626385
A21: Total expenses | E21: =SUM(E15:E20) -> 299 | F21: =SUM(F15:F20) -> 29844230 | H21: =SUM(H15:H20) -> 31546209 | T21: =+F21-H21 -> -1701979 | U21: =+T21-F21 -> -31546209
A23: Profit / (Loss) before exceptional and extraordinary items and tax | E23: =E12-E21 -> -30 | F23: =+F12-F21 -> -2956284 | H23: =+H12-H21 -> 19400000
A25: Extra Ordinary item
A26: Profit / (Loss) before tax | E26: =E23-E25 -> -30 | F26: =F23-SUM(F24:F25) -> -2956284 | H26: =H23-SUM(H24:H25) -> 19400000 | V26: =F26/F10 -> -0.26913186
U27: =75000 -> 75000 | V27: =ROUND(U27/100000,0) -> 1
A28: Tax expense | D28: ='18-26'!A189 -> 25 | U28: 50000 | V28: =ROUND(U28/100000,0) -> 1
A29: Current tax | E29: =ROUND(F29/10^5,0) -> 426 | F29: =+'Sch - PL'!E125+'Sch - PL'!E122 -> 42613709 | H29: =+'Sch - PL'!G125 -> 4035301 | J29: 15 | K29: 10639 | L29: =+F29-J29 -> 42613694 | M29: =+H29-K29 -> 4024662
A30: MAT credit entitlement | E30: =ROUND(F30/10^5,0) -> 0 | F30: =-'Sch - PL'!E122*0 -> 0 | H30: =-'Sch - PL'!G122*0-H31-1*0 -> 0 | J30: 5046 | K30: -168 | L30: =+F30-J30 -> -5046 | M30: =+H30-K30 -> 168
A31: MAT credit entitlement written off | E31: =ROUND(F31/10^5,0) -> 0 | H31: =ROUND(77348338.6220272/Master!$B$23,0)*0 -> 0 | K31: 77348 | L31: =+F31-J31 -> 0 | M31: =+H31-K31 -> -77348
A32: Deferred tax [net of MAT credit ₹ 31 ( 31 March 2024 : ₹ 4)] (refer note no 14) | E32: =ROUND(F32/10^5,0) -> 35 | F32: =+'Sch - PL'!E127-'Sch - PL'!E122+'Sch - PL'!E129 -> 3452021 | H32: =+'Sch - PL'!G127++'Sch - PL'!G129 -> -26030840 | J32: 107 | K32: -13 | L32: =+F32-J32 -> 3451914 | M32: =+H32-K32 -> -26030827 | T32: =+F32-H32 -> 29482861
A33: Buy back tax | F33: =+'Sch - PL'!E129*0 -> 0 | H33: =+'Sch - PL'!G129*0 -> 0 | J33: 0 | K33: 0 | L33: =+F33-J33 -> 0 | M33: =+H33-K33 -> 0
L34: =+F34-J34 -> 0 | M34: =+H34-K34 -> 0
A35: Total tax expenses | E35: =SUM(E29:E34) -> 461 | F35: =SUM(F29:F34) -> 46065730 | H35: =SUM(H29:H34) -> -21995539 | J35: 5168 | K35: 87806 | L35: =+F35-J35 -> 46060562 | M35: =+H35-K35 -> -22083345 | T35: =+F35-H35 -> 68061269 | U35: =+T35-F35 -> 21995539
A37: Profit / (Loss) after tax (A) | E37: =+E26-E35 -> -491 | F37: =+F26-F35 -> -49022014 | H37: =+H26-H35 -> 41395539 | I37: =+'PL Gr'!E459 -> -48218703 | J37: =+F37-I37 -> -803311.47 | T37: =+F37-H37 -> -90417553 | V37: =+'PL Gr'!E459 -> -48218703 | W37: =+F37-V37 -> -803311.47
A39: Other comprehensive income
A40: Items that will not be reclassified subsequently to profit or loss
A41: Remeasurement of the actuarial gain on defined benefit obligation (#) | E41: =ROUND(F41/10^5,0) -> 0 | F41: =-OCI!U5 -> -46765 | H41: =-OCI!S5 -> -30176 | T41: =+F41-H41 -> -16589
A42: Tax impact on above items (#) | E42: =ROUND(F42/10^5,0) -> 0 | F42: =-OCI!U6 -> 13010 | H42: =-OCI!S6 -> 8395 | T42: =+F42-H42 -> 4615
A43: Other comprehensive income / (loss) for the year (B) | E43: =SUM(E41:E42) -> 0 | F43: =SUM(F41:F42) -> -33755 | H43: =SUM(H41:H42) -> -21781 | T43: =+F43-H43 -> -11974
A45: Items that will be reclassified subsequently to profit or loss | H45: 0
A47: Other comprehensive income for the year | F47: 0 | H47: 0
A48: Total Other comprehensive income / (loss) for the year (A+B) | E48: =E37+E43 -> -491 | F48: =F37+F43 -> -49055769 | H48: =H37+H43 -> 41373758 | T48: =+F48-H48 -> -90429527 | U48: =+F48-T48 -> 41373758 | W48: =+'Sch - BS'!G223 -> -109379
W49: =+W48+F37 -> -49131393
A50: Basic and diluted earning / (loss) per equity share (₹) | D50: =+'Notes 28-35'!A261 -> 29 | F50: ='Notes 28-35'!J267 -> -4902.2014 | H50: ='Notes 28-35'!K267 -> 4139.5539 | W50: )
...

Sheet PL Gr
A1: =+Master!B2 -> Syntel Solutions (India) Private Limited | C1: Ind AS account codes
A2: ="Profit & Loss Grouping for the period ended " &Master!$B$5 -> Profit & Loss Grouping for the period ended 31st March 2025
A4: GL Code | B4: Account description | C4: PL Grouping | E4: =+'Sch - PL'!E5 -> 2025 | G4: =+'Sch - PL'!G5 -> 2024 | J4: Apr-20 to Dec-20 Fin | K4: Jan-21 to Mar-21 Fin | L4: Apr to Dec 19 Fin | M4: Mar 20 Fin | N4: Total IFRS Fin | O4: Difference
A6: 400010 | B6: =VLOOKUP(A6,'TB for financial'!A:B,2,0) -> Onsite/Offsite Revenues | C6: Revenue from operations | E6: =-VLOOKUP(A6,'TB for financial'!A:F,6,0) -> 0 | G6: =-VLOOKUP(A6,'TB for financial'!A:K,11,0) -> 0 | H6: 400010 | I6: 0 | J6: 0 | K6: 0 | L6: 0 | M6: 0 | N6: =+J6+K6 -> 0 | O6: =+E6-N6 -> 0 | Q6: #N/A
A7: 400020 | B7: =VLOOKUP(A7,'TB for financial'!A:B,2,0) -> Revenue Adjustments | C7: Revenue from operations | E7: =-VLOOKUP(A7,'TB for financial'!A:F,6,0) -> 0 | G7: =-VLOOKUP(A7,'TB for financial'!A:K,11,0) -> 0 | H7: #N/A | I7: #N/A | J7: 0 | K7: 0 | L7: 0 | M7: 0 | N7: =+J7+K7 -> 0 | O7: =+E7-N7 -> 0
A8: 400030 | B8: =VLOOKUP(A8,'TB for financial'!A:B,2,0) -> Offshore Revenue | C8: Revenue from operations | E8: =-VLOOKUP(A8,'TB for financial'!A:F,6,0) -> 0 | G8: =-VLOOKUP(A8,'TB for financial'!A:K,11,0) -> 0 | H8: 400030 | I8: 0 | J8: 0 | K8: 0 | L8: 0 | M8: 0 | N8: =+J8+K8 -> 0 | O8: =+E8-N8 -> 0
A9: 400050 | B9: =VLOOKUP(A9,'TB for financial'!A:B,2,0) -> Reimbursement of Expenses-REVE | C9: Revenue from operations | E9: =-VLOOKUP(A9,'TB for financial'!A:F,6,0) -> 0 | G9: =-VLOOKUP(A9,'TB for financial'!A:K,11,0) -> 0 | H9: 400050 | I9: 0 | J9: 0 | K9: 0 | L9: 0 | M9: 0 | N9: =+J9+K9 -> 0 | O9: =+E9-N9 -> 0
A10: 400060 | B10: =VLOOKUP(A10,'TB for financial'!A:B,2,0) -> Sales Incentives | C10: Revenue from operations | E10: =-VLOOKUP(A10,'TB for financial'!A:F,6,0) -> 0 | G10: =-VLOOKUP(A10,'TB for financial'!A:K,11,0) -> 0 | H10: #N/A | I10: #N/A | J10: 0 | K10: 0 | L10: 0 | M10: 0 | N10: =+J10+K10 -> 0 | O10: =+E10-N10 -> 0
A11: 400061 | B11: =VLOOKUP(A11,'TB for financial'!A:B,2,0) -> Volume Discount/Rebates | C11: Revenue from operations | E11: =-VLOOKUP(A11,'TB for financial'!A:F,6,0) -> 0 | G11: =-VLOOKUP(A11,'TB for financial'!A:K,11,0) -> 0 | H11: #N/A | I11: #N/A | J11: 0 | K11: 0 | L11: 0 | M11: 0 | N11: =+J11+K11 -> 0 | O11: =+E11-N11 -> 0
A12: 400110 | B12: =VLOOKUP(A12,'TB for financial'!A:B,2,0) -> Inter Unit Onsite/Offsite Reve | C12: Revenue from operations | E12: =-VLOOKUP(A12,'TB for financial'!A:F,6,0) -> 0 | G12: =-VLOOKUP(A12,'TB for financial'!A:K,11,0) -> 0 | H12: 400110 | I12: 0 | J12: 0 | K12: 0 | L12: 0 | M12: 0 | N12: =+J12+K12 -> 0 | O12: =+E12-N12 -> 0
A13: 400130 | B13: =VLOOKUP(A13,'TB for financial'!A:B,2,0) -> Inter Unit Offshore Revenue | C13: Revenue from operations | D13: 400130 | E13: =-VLOOKUP(A13,'TB for financial'!A:F,6,0) -> 0 | G13: =-VLOOKUP(A13,'TB for financial'!A:K,11,0) -> 0 | H13: 400130 | I13: 12678976 | J13: 8465942.5 | K13: 3718537.5 | L13: 0 | M13: 0 | N13: =+J13+K13 -> 12184480 | O13: =+E13-N13 -> -12184480 | P13: 400130 | Q13: #N/A | R13: =+E13-Q13 -> #N/A
A14: 400040 | B14: =VLOOKUP(A14,'TB for financial'!A:B,2,0) -> Domestic Direct Revenue | C14: Revenue from operations | E14: =-VLOOKUP(A14,'TB for financial'!A:F,6,0) -> 0 | G14: =-VLOOKUP(A14,'TB for financial'!A:K,11,0) -> 0 | H14: #N/A | I14: #N/A | J14: 0 | K14: 0 | L14: 0 | M14: 0 | N14: =+J14+K14 -> 0 | O14: =+E14-N14 -> 0
A15: 706361 | B15: =VLOOKUP(A15,'TB for financial'!A:B,2,0) -> Sales of Services. Interco EXP | C15: Revenue from operations | D15: 706361 | E15: =-VLOOKUP(A15,'TB for financial'!A:F,6,0) -> 10587551 | G15: =-VLOOKUP(A15,'TB for financial'!A:K,11,0) -> 13298075 | H15: 706361 | I15: -9954016.9 | J15: 0 | K15: 0 | L15: 0 | M15: 0 | N15: =+J15+K15 -> 0 | O15: =+E15-N15 -> 10587551
A16: 779000 | B16: =VLOOKUP(A16,'TB for financial'!A:B,2,0) -> Revenue Offshore Netting Billing | C16: Revenue from operations | E16: =-VLOOKUP(A16,'TB for financial'!A:F,6,0) -> 396967.87 | G16: =-VLOOKUP(A16,'TB for financial'!A:K,11,0) -> 1182131.3 | H16: 779000
B18: Sale of services | E18: =SUM(E6:E17) -> 10984519 | G18: =SUM(G6:G17) -> 14480207 | J18: =SUM(J6:J17) -> 8465942.5 | K18: =SUM(K6:K17) -> 3718537.5 | L18: =SUM(L6:L17) -> 0 | M18: =SUM(M6:M17) -> 0 | N18: =SUM(N6:N17) -> 12184480 | O18: =SUM(O6:O17) -> -1596929.2
A20: 400021 | B20: =VLOOKUP(A20,'TB for financial'!A:B,2,0) -> Local Sales - India | C20: Revenue from operations | D20: 400021 | E20: =-VLOOKUP(A20,'TB for financial'!A:F,6,0) -> 0 | G20: =-VLOOKUP(A20,'TB for financial'!A:K,11,0) -> 0 | H20: 400021 | I20: 705115.68 | J20: 541150.19 | K20: 0 | L20: 0 | M20: 0 | N20: =+J20+K20 -> 541150.19 | O20: =+E20-N20 -> -541150.19 | P20: 400021 | Q20: #N/A | R20: =+E20-Q20 -> #N/A
A21: 400140 | B21: =VLOOKUP(A21,'TB for financial'!A:B,2,0) -> Finder Fees - Inter company | C21: Revenue from operations | E21: =-VLOOKUP(A21,'TB for financial'!A:F,6,0) -> 0 | G21: =-VLOOKUP(A21,'TB for financial'!A:K,11,0) -> 0 | H21: 400140 | I21: 0 | J21: 0 | K21: 0 | L21: 0 | M21: 0 | N21: =+J21+K21 -> 0 | O21: =+E21-N21 -> 0 | P21: 400140 | Q21: #N/A | R21: =+E21-Q21 -> #N/A
A22: 400141 | B22: =VLOOKUP(A22,'TB for financial'!A:B,2,0) -> Finder Fee-InterCompany Domes | C22: Revenue from operations | E22: =-VLOOKUP(A22,'TB for financial'!A:F,6,0) -> 0 | G22: =-VLOOKUP(A22,'TB for financial'!A:K,11,0) -> 0 | H22: 400141 | I22: 0 | J22: 0 | K22: 0 | L22: 0 | M22: 0 | N22: =+J22+K22 -> 0 | O22: =+E22-N22 -> 0
B24: Other operating income | E24: =SUM(E20:E23) -> 0 | G24: =SUM(G20:G23) -> 0 | J24: =SUM(J20:J23) -> 541150.19 | K24: =SUM(K20:K23) -> 0 | L24: =SUM(L20:L23) -> 0 | M24: =SUM(M20:M23) -> 0 | N24: =SUM(N20:N23) -> 541150.19 | O24: =SUM(O20:O23) -> -541150.19
A26: 601010 | B26: =VLOOKUP(A26,'TB for financial'!A:B,2,0) -> Interest Income Taxable | C26: Other income | D26: 601010 | E26: =-VLOOKUP(A26,'TB for financial'!A:F,6,0) -> 0 | G26: =-VLOOKUP(A26,'TB for financial'!A:K,11,0) -> 0 | H26: 601010 | I26: -5109640.7 | J26: 6200594.7 | K26: 1519151.1 | L26: 0 | M26: 0 | N26: =+J26+K26 -> 7719745.8 | O26: =+E26-N26 -> -7719745.8
A27: 601011 | B27: =VLOOKUP(A27,'TB for financial'!A:B,2,0) -> Interest Income Non Taxable | C27: Other income | E27: =-VLOOKUP(A27,'TB for financial'!A:F,6,0) -> 0 | G27: =-VLOOKUP(A27,'TB for financial'!A:K,11,0) -> 0 | H27: 601011 | I27: 0 | J27: 0 | K27: 0 | L27: 0 | M27: 0 | N27: =+J27+K27 -> 0 | O27: =+E27-N27 -> 0
A28: 601012 | B28: =VLOOKUP(A28,'TB for financial'!A:B,2,0) -> Dividend Income | C28: Other income | E28: =-VLOOKUP(A28,'TB for financial'!A:F,6,0) -> 0 | G28: =-VLOOKUP(A28,'TB for financial'!A:K,11,0) -> 0 | H28: 601012 | I28: 0 | J28: 0 | K28: 0 | L28: 0 | M28: 0 | N28: =+J28+K28 -> 0 | O28: =+E28-N28 -> 0
A29: 601013 | B29: =VLOOKUP(A29,'TB for financial'!A:B,2,0) -> Profit on redemption of mutual fund | C29: Other income | E29: =-VLOOKUP(A29,'TB for financial'!A:F,6,0) -> 0 | G29: =-VLOOKUP(A29,'TB for financial'!A:K,11,0) -> 0 | H29: 601013 | I29: 0 | J29: 1.4551915e-11 | K29: 0 | L29: 0 | M29: 0 | N29: =+J29+K29 -> 1.4551915e-11 | O29: =+E29-N29 -> -1.4551915e-11 | P29: 601013 | Q29: #N/A | R29: =+E29-Q29 -> #N/A
A30: 601033 | B30: =VLOOKUP(A30,'TB for financial'!A:B,2,0) -> MF unrealised gain (IndAS) | C30: Other income | E30: =-VLOOKUP(A30,'TB for financial'!A:F,6,0) -> 0 | G30: =-VLOOKUP(A30,'TB for financial'!A:K,11,0) -> 0 | H30: 601033 | I30: 0 | J30: 0 | K30: 0 | L30: 0 | M30: 0 | N30: =+J30+K30 -> 0 | O30: =+E30-N30 -> 0 | P30: 601033
A31: 601014 | B31: =VLOOKUP(A31,'TB for financial'!A:B,2,0) -> Miscellaneous Income | C31: Other income | E31: =-VLOOKUP(A31,'TB for financial'!A:F,6,0) -> 0 | G31: =-VLOOKUP(A31,'TB for financial'!A:K,11,0) -> 0 | H31: 601014 | I31: 0 | J31: 100000 | K31: -22105.98 | L31: 0 | M31: 0 | N31: =+J31+K31 -> 77894.02 | O31: =+E31-N31 -> -77894.02
A32: 601017 | B32: =VLOOKUP(A32,'TB for financial'!A:B,2,0) -> Forex Interest Income Taxable | C32: Other income | E32: =-VLOOKUP(A32,'TB for financial'!A:F,6,0) -> 0 | G32: =-VLOOKUP(A32,'TB for financial'!A:K,11,0) -> 0 | H32: 601017 | I32: 0 | J32: 0 | K32: 0 | L32: 0 | M32: 0 | N32: =+J32+K32 -> 0 | O32: =+E32-N32 -> 0
A33: 601015 | B33: =VLOOKUP(A33,'TB for financial'!A:B,2,0) -> Dividend - Interco | C33: Other income | E33: =-VLOOKUP(A33,'TB for financial'!A:F,6,0) -> 0 | G33: =-VLOOKUP(A33,'TB for financial'!A:K,11,0) -> 0 | H33: #N/A | I33: #N/A | J33: 0 | K33: 0 | L33: 0 | M33: 0 | N33: =+J33+K33 -> 0 | O33: =+E33-N33 -> 0
A34: 601016 | B34: =VLOOKUP(A34,'TB for financial'!A:B,2,0) -> Inter-Company Revenue | C34: Other income | E34: =-VLOOKUP(A34,'TB for financial'!A:F,6,0) -> 0 | G34: =-VLOOKUP(A34,'TB for financial'!A:K,11,0) -> 0 | H34: #N/A | I34: #N/A | J34: 0 | K34: 0 | L34: 0 | M34: 0 | N34: =+J34+K34 -> 0 | O34: =+E34-N34 -> 0
A35: 601018 | B35: =VLOOKUP(A35,'TB for financial'!A:B,2,0) -> Employee - Interest on Loan | C35: Other income | D35: 601018 | E35: =-VLOOKUP(A35,'TB for financial'!A:F,6,0) -> 0 | G35: =-VLOOKUP(A35,'TB for financial'!A:K,11,0) -> 0 | H35: 601018 | I35: -1375 | J35: 42 | K35: 0 | L35: 0 | M35: 0 | N35: =+J35+K35 -> 42 | O35: =+E35-N35 -> -42
A36: 601020 | B36: Other Income - Non Taxable | C36: Other income | E36: =-VLOOKUP(A36,'TB for financial'!A:F,6,0) -> 0 | G36: =-VLOOKUP(A36,'TB for financial'!A:K,11,0) -> 0 | H36: #N/A | I36: #N/A | J36: 0 | K36: 0 | L36: 0 | M36: 0 | N36: =+J36+K36 -> 0 | O36: =+E36-N36 -> 0
A37: 601090 | B37: =VLOOKUP(A37,'TB for financial'!A:B,2,0) -> Interco Rent - Income | C37: Other income | E37: =-VLOOKUP(A37,'TB for financial'!A:F,6,0) -> 0 | G37: =-VLOOKUP(A37,'TB for financial'!A:K,11,0) -> 0 | H37: 601090 | I37: 0 | J37: 0 | K37: 0 | L37: 0 | M37: 0 | N37: =+J37+K37 -> 0 | O37: =+E37-N37 -> 0
A38: 601032 | B38: =VLOOKUP(A38,'TB for financial'!A:B,2,0) -> Interest income IC Dep (IndAS) | C38: Other income | E38: =-VLOOKUP(A38,'TB for financial'!A:F,6,0) -> 0 | G38: =-VLOOKUP(A38,'TB for financial'!A:K,11,0) -> 0 | H38: 601032 | I38: 0 | J38: 0 | K38: 0 | L38: 0 | M38: 0 | N38: =+J38+K38 -> 0 | O38: =+E38-N38 -> 0 | P38: 601032
A39: 601023 | B39: =VLOOKUP(A39,'TB for financial'!A:B,2,0) -> Interest Exp on Lease Liab | C39: Finance | E39: =-VLOOKUP(A39,'TB for financial'!A:F,6,0) -> 0 | G39: =-VLOOKUP(A39,'TB for financial'!A:K,11,0) -> 0 | H39: 601023 | I39: 0
A40: 704040 | B40: =VLOOKUP(A40,'TB for financial'!A:B,2,0) -> Interest income on Cash at Bank-Other | C40: Other income | D40: 704040 | E40: =-VLOOKUP(A40,'TB for financial'!A:F,6,0) -> -4094148.5 | G40: =-VLOOKUP(A40,'TB for financial'!A:K,11,0) -> 15878069 | H40: 704040 | I40: -13661470 | J40: 0 | K40: 0 | L40: 0 | M40: 0 | N40: =+J40+K40 -> 0 | O40: =+E40-N40 -> -4094148.5
A41: 704670 | B41: =VLOOKUP(A41,'TB for financial'!A:B,2,0) -> Other Financial Income | C41: Other income | E41: =-VLOOKUP(A41,'TB for financial'!A:F,6,0) -> 0 | G41: =-VLOOKUP(A41,'TB for financial'!A:K,11,0) -> 20393931
A42: 762510 | B42: =VLOOKUP(A42,'TB for financial'!A:B,2,0) -> Int Income-Personal Loan | C42: Other income | D42: 762510 | E42: =-VLOOKUP(A42,'TB for financial'!A:F,6,0) -> 6928 | G42: =-VLOOKUP(A42,'TB for financial'!A:K,11,0) -> 5679 | H42: 762510 | I42: -2167 | J42: 0 | K42: 0 | L42: 0 | M42: 0 | N42: =+J42+K42 -> 0 | O42: =+E42-N42 -> 6928
A43: 762511 | B43: =VLOOKUP(A43,'TB for financial'!A:B,2,0) -> Interest Income-Deposits | C43: Other income | D43: 762511 | E43: =-VLOOKUP(A43,'TB for financial'!A:F,6,0) -> 217626.97 | G43: =-VLOOKUP(A43,'TB for financial'!A:K,11,0) -> 188322.99 | H43: 762511 | I43: -304021.7
A44: 664011 | B44: =VLOOKUP(A44,'TB for financial'!A:B,2,0) -> Financial interests on lease liability Real estate | C44: Finance costs | D44: 664011 | E44: =VLOOKUP(A44,'TB for financial'!A:F,6,0) -> 401655.69 | G44: =VLOOKUP(A44,'TB for financial'!A:K,11,0) -> 638521.58 | H44: 664011 | I44: 180595.34
A45: 764501 | B45: FIN INC TERM DEPO | C45: Finance costs | E45: =-VLOOKUP(A45,'TB for financial'!A:F,6,0) -> 19689988
B47: Other Income | E47: =SUM(E26:E46) -> 16222051 | G47: =SUM(G26:G46) -> 37104524 | J47: =SUM(J26:J46) -> 6300636.7 | K47: =SUM(K26:K46) -> 1497045.1 | L47: =SUM(L26:L46) -> 0 | M47: =SUM(M26:M46) -> 0 | N47: =SUM(N26:N46) -> 7797681.8 | O47: =SUM(O26:O46) -> -11884902
...

Sheet Macro1

Sheet Sch - PL
A1: =+Master!$B$2 -> Syntel Solutions (India) Private Limited
A2: ="Notes forming part of financial statements for the period ended " &Master!$B$5 -> Notes forming part of financial statements for the period ended 31st March 2025
G4: =+Master!B24 -> (Rs.)
E5: =+Master!$B$7 -> 2025 | G5: =+Master!$B$13 -> 2024
A6: Revenue
A7: Revenue | E7: =ROUND(('PL Gr'!E18)/Master!$B$23,0)+ROUND(('PL Gr'!E20)/Master!$B$23,0) -> 10984519 | G7: =ROUND(('PL Gr'!G18)/Master!$B$23,0)+ROUND(('PL Gr'!G20)/Master!$B$23,0) -> 14480207
A8: Other operating income | E8: =ROUND(('PL Gr'!E24)/Master!$B$23,0)-ROUND(('PL Gr'!E20)/Master!$B$23,0) -> 0 | G8: =ROUND(('PL Gr'!G24)/Master!$B$23,0)-ROUND(('PL Gr'!G20)/Master!$B$23,0) -> 0
E10: =SUM(E6:E9) -> 10984519 | G10: =SUM(G6:G9) -> 14480207
A12: Gain(Loss) on Exchange Fluctation
A14: Exchange gain(loss) - notional
A15: Exchange gain(loss) - actual | E15: =-(-ROUND(('PL Gr'!E414+'PL Gr'!E418+'PL Gr'!E420+'PL Gr'!E421+'PL Gr'!E422+'PL Gr'!E423)/Master!$B$23,0)-ROUND(('PL Gr'!E415+'PL Gr'!E419+'PL Gr'!E424+'PL Gr'!E425+'PL Gr'!E426)/Master!$B$23,0)) -> 83032
A16: Exchange gain(loss) - derivatives | E16: =ROUND('PL Gr'!E417/Master!$B$23,0) -> 0 | G16: =ROUND('PL Gr'!G417/Master!$B$23,0) -> 0
A18: Total | E18: =SUM(E13:E17) -> 83032 | G18: =SUM(G13:G17) -> 0
A22: Other Income
A23: Interest Income
A24: Bank Deposit and income tax refund | E24: =ROUND(SUM('PL Gr'!E26+'PL Gr'!E27+'PL Gr'!E32+'PL Gr'!E40+'PL Gr'!E42+'PL Gr'!E45)/Master!$B$23,0) -> 15602768 | G24: =ROUND(SUM('PL Gr'!G26+'PL Gr'!G27+'PL Gr'!G32+'PL Gr'!G40+'PL Gr'!G42)/Master!$B$23,0) -> 15883748
A25: Unwinding of discount on security deposits | E25: =ROUND(('PL Gr'!E38+'PL Gr'!E43)/Master!$B$23,0) -> 217627 | G25: =ROUND(('PL Gr'!G38+'PL Gr'!G43)/Master!$B$23,0) -> 188323
A26: Others | E26: =ROUND('PL Gr'!E35/Master!$B$23,0) -> 0 | G26: =ROUND('PL Gr'!G35/Master!$B$23,0) -> 0
E27: =SUM(E24:E26) -> 15820395 | G27: =SUM(G24:G26) -> 16072071
A28: Dividend Income
A29: Preference Shares | E29: =ROUND(SUM('PL Gr'!E28+'PL Gr'!E33)/Master!$B$23,0) -> 0 | G29: =ROUND(SUM('PL Gr'!G28+'PL Gr'!G33)/Master!$B$23,0) -> 0
A31: Net Gain (Loss) on sale of Investments
A32: Profit on sale of mutual fund units | E32: =ROUND('PL Gr'!E29/Master!$B$23,0) -> 0 | G32: =ROUND('PL Gr'!G29/Master!$B$23,0) -> 0
A33: Unrealised gain on mutual fund units | E33: =ROUND('PL Gr'!E30/Master!$B$23,0) -> 0 | G33: =ROUND('PL Gr'!G30/Master!$B$23,0) -> 0
A34: Interest income from financial assets at amortised cost | E34: =ROUND('PL Gr'!E34/Master!$B$23,0) -> 0 | G34: =ROUND('PL Gr'!G34/Master!$B$23,0) -> 0
A36: Profit on sale of fixed asset | E36: =IF('PL Gr'!E358>0,ROUND('PL Gr'!E358/Master!$B$23,0),0) -> 0 | G36: =IF('PL Gr'!G358>0,ROUND('PL Gr'!G358/Master!$B$23,0),0) -> 0
A37: Rent Income | E37: =ROUND((+'PL Gr'!E37)/Master!$B$23,0) -> 0 | G37: =ROUND((+'PL Gr'!G37)/Master!$B$23,0) -> 0
A39: Miscellaneous Income | E39: =ROUND(('PL Gr'!E31+'PL Gr'!E41)/Master!$B$23,0) -> 0 | G39: =ROUND(('PL Gr'!G31+'PL Gr'!G41)/Master!$B$23,0) -> 20393931
A41: Total | E41: =SUM(E27:F40) -> 15820395 | G41: =SUM(G27:G40) -> 36466002
A46: Employee benefit expenses
A47: Salary, wages and bonus | E47: =ROUND('PL Gr'!E104/Master!$B$23,0)-E48-E49 -> 6356865 | G47: =ROUND('PL Gr'!G104/Master!$B$23,0)-G48-G49 -> 7978343 | I47: =E47-G47 -> -1621478
A48: Gratuity Expenses | E48: =ROUND(('PL Gr'!E64+'PL Gr'!E100)/Master!$B$23,0) -> 248295 | G48: =ROUND(('PL Gr'!G64+'PL Gr'!G100)/Master!$B$23,0) -> 293948 | I48: =E48-G48 -> -45653
A49: Compensated absences | E49: =ROUND(('PL Gr'!E50+'PL Gr'!E95)/Master!$B$23,0) -> 54162 | G49: =ROUND(('PL Gr'!G50+'PL Gr'!G95)/Master!$B$23,0) -> 43143 | I49: =E49-G49 -> 11019
A50: Contribution to Provident and other funds | E50: =ROUND('PL Gr'!E150/Master!$B$23,0) -> 115383 | G50: =ROUND('PL Gr'!G150/Master!$B$23,0) -> 143256 | I50: =E50-G50 -> -27873
A51: Staff Welfare Expenses | E51: =ROUND('PL Gr'!E134/Master!$B$23,0) -> 293709 | G51: =ROUND('PL Gr'!G134/Master!$B$23,0) -> 248332 | I51: =E51-G51 -> 45377
A53: Total | E53: =SUM(E47:E52) -> 7068414 | G53: =SUM(G47:G52) -> 8707022 | I53: =SUM(I47:I52) -> -1638608
A56: Finance Costs
A57: Bank charges
A58: Interest on shortfall of payment of advance tax
A59: Interest paid
...

Sheet Sch - BS
A1: =+Master!$B$2 -> Syntel Solutions (India) Private Limited
A2: =BS!A2 -> 0
A4: ="Notes forming part of financial statements as at " &Master!$B$5 -> Notes forming part of financial statements as at 31st March 2025 | G4: =+Master!B24 -> (Rs.)
G5: =+Master!$B$7 -> 2025 | I5: =Master!$B$13 -> 2024
A6: Non Currents assets
A8: Property, Plant and Equipment
A9: Property, Plant and Equipment | G9: =+ROUND(SUM('BS Gr'!D543+'BS Gr'!D565)/Master!$B$23,0) -> -1 | I9: =+ROUND(SUM('BS Gr'!F543+'BS Gr'!F565)/Master!$B$23,0) -> -1 | J9: =+G9-I9 -> 0
A10: Intangible assets | G10: =+ROUND((SUM('BS Gr'!D571)+SUM('BS Gr'!D576)+1)/Master!$B$23,0) -> 0 | I10: =+ROUND((SUM('BS Gr'!F571)+SUM('BS Gr'!F576)+1)/Master!$B$23,0) -> 0 | J10: =+G10-I10 -> 0
A11: Capital working in progress | G11: =ROUND('BS Gr'!D591/Master!$B$23,0) -> 0 | I11: =ROUND('BS Gr'!F591/Master!$B$23,0) -> 0 | J11: =+G11-I11 -> 0
A13: Total | G13: =SUM(G8:G12) -> -1 | I13: =SUM(I8:I12) -> -1 | J13: =+G13-I13 -> 0
A15: Financial assets
A16: Investments
A17: Investment in 3% Cumulative Redeemable Preference shares
A18: -Syntel International Private Limited | G18: =ROUND('BS Gr'!I84/Master!$B$23,0)-G28 -> 0 | I18: =ROUND('BS Gr'!M84/Master!$B$23,0)-I28 -> 0
A19: 93,900 (2016 - 54,200) shares of Rs.10 each fully paid-up
A21: -Trizetto Syntel Services (India) Private Limited | G21: =ROUND('BS Gr'!I88/Master!$B$23,0) -> 0 | I21: =ROUND('BS Gr'!M88/Master!$B$23,0) -> 0
A22: 11,200 (2016 - 11,200) shares of Rs. 10 each fully paid-up
A24: -Syntel Global Private Limited | G24: =ROUND('BS Gr'!I87/Master!$B$23,0) -> 0 | I24: =ROUND('BS Gr'!M87/Master!$B$23,0) -> 0
A25: Nil (2016 - Nil) shares of Rs. 10 each fully paid-up
A27: 0% Cumulative Redeemable Preference shares
A28: -Syntel International Private Limited | G28: =ROUND(0/Master!$B$23,0) -> 0 | I28: =ROUND(0/Master!$B$23,0) -> 0
A29: 284,777 (2016 - 437,301) shares of Rs.10 each fully paid-up
A31: Total | G31: =SUM(G14:G30) -> 0 | I31: =SUM(I14:I30) -> 0
A33: Loans | G33: =ROUND('BS Gr'!M257/Master!$B$23,0) -> 0 | I33: =ROUND('BS Gr'!M257/Master!$B$23,0) -> 0
A35: Total | G35: =SUM(G33:G34) -> 0 | I35: =SUM(I33:I34) -> 0
A37: Other financial assets
A38: Security deposits | G38: =ROUND('BS Gr'!I502/Master!$B$23,0) -> 0 | I38: =ROUND('BS Gr'!M502/Master!$B$23,0) -> 0 | J38: =+G38-I38 -> 0
A39: Rental deposits | J39: =+G39-I39 -> 0
A40: to parties other than related parties | G40: =ROUND(('BS Gr'!I462)/Master!$B$23,0)-G42-G41-G69 -> 0 | I40: =ROUND(('BS Gr'!M462)/Master!$B$23,0)-I42-I41-I69 -> 0 | J40: =+G40-I40 -> 0
A41: to related parties | G41: =ROUND('BS Gr'!I462/Master!$B$23,0)-G69 -> 0 | I41: =ROUND('BS Gr'!M462/Master!$B$23,0)-I69 -> 2602786 | J41: =+G41-I41 -> -2602786 | K41: =+J41+CF!F17+36105 -> -2784308
A42: Doubtful | G42: =+-ROUND('BS Gr'!I449/Master!$B$23,0) -> 0 | I42: =+-ROUND('BS Gr'!M449/Master!$B$23,0) -> 0 | J42: =+G42-I42 -> 0
G43: =SUM(G40:G42) -> 0 | I43: =SUM(I40:I42) -> 2602786 | J43: =+G43-I43 -> -2602786
A44: Less: Provision for doubtful deposits | G44: =-G42 -> 0 | I44: =-I42 -> 0 | J44: =+G44-I44 -> 0
G45: =SUM(G43:G44) -> 0 | I45: =SUM(I43:I44) -> 2602786 | J45: =+G45-I45 -> -2602786
J46: =+G46-I46 -> 0
A47: Total | G47: =G38+G45 -> 0 | I47: =I38+I45 -> 2602786 | J47: =+G47-I47 -> -2602786
A49: Deferred tax assets (net) | G49: =ROUND(('BS Gr'!I882-'BS Gr'!I871*0)/Master!$B$23,0)-G51 -> -3328863 | I49: =ROUND(('BS Gr'!M882-'BS Gr'!M871*0)/Master!$B$23,0)-I51 -> -6767874 | J49: =+G49-I49 -> 3439011
A50: MAT Credit entitlement | G50: =-ROUND('BS Gr'!I376/Master!$B$23,0) -> 0 | I50: =-ROUND('BS Gr'!M376/Master!$B$23,0) -> 0
A51: Tax on buy back pf preference shares | G51: =ROUND(('BS Gr'!I879+'BS Gr'!I876)/Master!$B$23,0) -> 0 | I51: =ROUND(('BS Gr'!M879+'BS Gr'!M876)/Master!$B$23,0) -> 0
J52: =+G52-I52 -> 0
...

Sheet TB for financial
A1: =+Master!B2 -> Syntel Solutions (India) Private Limited | D1: Ind AS account codes
A2: ="Annexure to Grouping " &Master!$B$5 -> Annexure to Grouping 31st March 2025
