Workbook
Name \0: #REF!
Name \A: #REF!
Name \B: #REF!
Name \C: #REF!
Name \D: #REF!
Name \E: #REF!
Name \f: #N/A
Name \GP: [1]A!$D$2748
Name \H: [1]A!$D$2882
Name \I: #REF!
Name \INC: '[2]jan''04'!#REF!
Name \K: [1]A!$D$2550
Name \L: [1]A!$D$2629
Name \M: [1]A!$D$2545
Name \N: [1]A!$D$2656
Name \O: #REF!
Name \Q: [1]A!$D$2173
Name \R: #REF!
Name \s: #REF!
Name \T: [1]A!$D$2781
Name \W: [1]A!$D$2120
Name \x: #N/A
Name \Y: [1]A!$D$2748
Name \z: #N/A
Name ________PG1: #REF!
Name _______DEP390: #REF!
Name _______PG1: #REF!
Name ______DEP390: #REF!
Name ______PG1: #REF!
Name _____DEP390: #REF!
Name _____PG1: #REF!
Name ____DAT1: [3]sent!#REF!
Name ____DAT10: [4]Sheet1!#REF!
Name ____DAT11: [4]Sheet1!#REF!
Name ____DAT12: [4]Sheet1!#REF!
Name ____DAT3: [3]sent!#REF!
Name ____DAT4: [3]sent!#REF!
Name ____DAT6: [3]sent!#REF!
Name ____DAT9: [4]Sheet1!#REF!
Name ____DEP390: #REF!
Name ____PG1: #REF!
Name ____PG10: #REF!
Name ____PG11: #REF!
Name ____PG13: '[5]#REF'!#REF!
Name ____PG3: #REF!
Name ____PG8: #REF!
Name ___1ANNEX_C_1: #REF!
Name ___DAT1: '[6]jan''04'!#REF!
Name ___DAT10: #REF!
Name ___DAT11: #REF!
Name ___DAT12: '[6]jan''04'!#REF!
Name ___DAT13: '[6]jan''04'!#REF!
Name ___DAT14: '[6]jan''04'!#REF!
Name ___DAT15: #REF!
Name ___DAT16: #REF!
Name ___DAT17: #REF!
Name ___DAT18: #REF!
Name ___DAT19: #REF!
Name ___DAT2: '[6]jan''04'!#REF!
Name ___DAT20: '[6]jan''04'!#REF!

Sheet BS
A1: =PL!A1 -> Client: | B1: Name | F1: Legends
A2: Analysis of Balance sheet | F2: a | G2: Traced to Financials for the year ended 31 March 20XX
A3: As at 31 March XX vs 31 March XXX | F3: b | G3: Traced to Financials for the year ended 31 March 20XX
F4: e | G4: Recomputed
A6: Scope: All variances above of TE i.e. XXX and (+/-) 10% have been selected for further checking. Further, some accounts on qualitative grounds have been explained in the analysis below.
C7: b | D7: a | E7: e | F7: e | G7: (Rs. In …..............................)
A8: Particulars | B8: Note number | C8: As at 31 March XXX | D8: As at 31 March XXX | E8: Variance (Absolute) | F8: Variance % | G8: Remarks
A12: To be fetched from actual Balance Sheet | B12: 1 | E12: =C12-D12 -> 0 | F12: =E12/D12 -> #DIV/0!
E13: =C13-D13 -> 0 | F13: =E13/D13 -> #DIV/0!
E14: =C14-D14 -> 0 | F14: =E14/D14 -> #DIV/0!
E15: =C15-D15 -> 0 | F15: =E15/D15 -> #DIV/0!
E16: =C16-D16 -> 0 | F16: =E16/D16 -> #DIV/0!
E18: =C18-D18 -> 0 | F18: =E18/D18 -> #DIV/0!
E19: =C19-D19 -> 0 | F19: =E19/D19 -> #DIV/0!
E20: =C20-D20 -> 0 | F20: =E20/D20 -> #DIV/0!
E21: =C21-D21 -> 0 | F21: =E21/D21 -> #DIV/0!
E22: =C22-D22 -> 0 | F22: =E22/D22 -> #DIV/0!
C23: =SUM(C12:C22) -> 0 | D23: =SUM(D12:D22) -> 0 | E23: =SUM(E12:E22) -> 0
E25: =C25-D25 -> 0 | F25: =E25/D25 -> #DIV/0!
E27: =C27-D27 -> 0 | F27: =E27/D27 -> #DIV/0!
E28: =C28-D28 -> 0 | F28: =E28/D28 -> #DIV/0!
E29: =C29-D29 -> 0 | F29: =E29/D29 -> #DIV/0!
E30: =C30-D30 -> 0 | F30: =E30/D30 -> #DIV/0!
E31: =C31-D31 -> 0 | F31: =E31/D31 -> #DIV/0!
E32: =C32-D32 -> 0 | F32: =E32/D32 -> #DIV/0!
C33: =SUM(C25:C32) -> 0 | D33: =SUM(D25:D32) -> 0 | E33: =SUM(E25:E32) -> 0
C34: =C33+C23 -> 0 | D34: =D33+D23 -> 0
E38: =C38-D38 -> 0 | F38: =E38/D38 -> #DIV/0!
E39: =C39-D39 -> 0 | F39: =E39/D39 -> #DIV/0!
C40: =SUM(C38:C39) -> 0 | D40: =SUM(D38:D39) -> 0 | E40: =SUM(E38:E39) -> 0
E44: =C44-D44 -> 0 | F44: =E44/D44 -> #DIV/0!
E45: =C45-D45 -> 0 | F45: =E45/D45 -> #DIV/0!
E46: =C46-D46 -> 0 | F46: =E46/D46 -> #DIV/0!
E47: =C47-D47 -> 0 | F47: =E47/D47 -> #DIV/0!
E48: =C48-D48 -> 0 | F48: =E48/D48 -> #DIV/0!
E52: =C52-D52 -> 0 | F52: =E52/D52 -> #DIV/0!
E53: =C53-D53 -> 0 | F53: =E53/D53 -> #DIV/0!
E54: =C54-D54 -> 0 | F54: =E54/D54 -> #DIV/0!
E55: =C55-D55 -> 0 | F55: =E55/D55 -> #DIV/0!
E56: =C56-D56 -> 0 | F56: =E56/D56 -> #DIV/0!
...

Sheet PL
A1: Client: | C1: Name | F1: Legends
A2: Analysis of Statement of Profit and Loss | F2: a | G2: Traced to Financials for the year ended 31 March 20XX
A3: For the year ended 31 March XXX vs 31 March XXX | F3: b | G3: Traced to Financials for the year ended 31 March 20XX
F4: e | G4: Recomputed
A6: Scope: All variances above of TE i.e. XXXX and (+/-) 10% have been selected for further checking. Further, some accounts on qualitative grounds have been explained in the analysis below.
C8: b | D8: a | E8: e | F8: e | G8: (Rs. In …..............................)
A9: Particulars | B9: Note number | C9: For the Year ended 31 March XXX | D9: For the Year ended 31 March XXX | E9: Absolute Variance | F9: Variance % | G9: Remarks
A12: To be fetched from actual profit and Loss | F12: =E12/D12 -> #DIV/0!
F13: =E13/D13 -> #DIV/0!
F17: =E17/D17 -> #DIV/0!
F18: =E18/D18 -> #DIV/0!
F19: =E19/D19 -> #DIV/0!
F20: =E20/D20 -> #DIV/0!
F21: =E21/D21 -> #DIV/0!
F22: =E22/D22 -> #DIV/0!
F23: =E23/D23 -> #DIV/0!
F28: 0
F29: 0

Sheet Sheet3
A1: Units consumed for electricity expenses
A2: Litre consumed for fuel expenses
A3: Units sold,stock transfer and bifurcation of units sold in domestic and export
A4: Reason for decrease in legal and prfessional expenses
A5: Reason for decrease in testing and labrotar expenses
A6: Reason for the decrease in marketing expense as % to sales. I have documented that no seminars have taken place.
A7: Reason for the decrease in canteen subsidy expense as
A8: % of salary decrease of senior management

Sheet 3-4
A1: =PL!A1 -> Client: | H1: Legend:
A2: Analysis of Notes to Accounts | H2: a | I2: Traced to Financials for the year ended 31 March 20XX
H3: b | I3: Traced to Financials for the year ended 31 March 20XX
H4: j | I4: Linked
H5: e | I5: Recomputed
H6: h | I6: Immaterial. Hence ignored
B8: Property Plant and Equipment | C8: a | D8: b | E8: e | F8: e
B9: Particulars | C9: As at 31st March 20XX | D9: As at 31st March 20XX | E9: Variance | F9: Variance % | G9: Remarks
B11: Gross Block
B12: Accumulated Depreciation
B14: Total
B16: Intangible Assets | C16: a | D16: b | E16: e | F16: e
B17: Particulars | C17: As at 31st March 20XX | D17: As at 31st March 20XX | E17: Variance | F17: Variance % | G17: Remarks
B19: Gross Block
B20: Accumulated Depreciation
B22: Total
B24: Right of Use Assets | C24: a | D24: b | E24: e | F24: e
B25: Particulars | C25: As at 31st March 20XX | D25: As at 31st March 20XX | E25: Variance | F25: Variance % | G25: Remarks
B27: Gross Block
B28: Accumulated Depreciation
B30: Total

Sheet 10-17
A1: =PL!A1 -> Client: | H1: Legend:
A2: Analysis of Notes to Accounts | H2: a | I2: Traced to Financials for the year ended 31 March 20XX
H3: b | I3: Traced to Financials for the year ended 31 March 20XX
H4: j | I4: Linked
H5: e | I5: Recomputed
H6: h | I6: Immaterial. Hence ignored

Sheet 5-9
A1: =PL!A1 -> Client: | H1: Legend:
A2: Analysis of Notes to Accounts | H2: a | I2: Traced to Financials for the year ended 31 March 20XX
H3: b | I3: Traced to Financials for the year ended 31 March 20XX
H4: j | I4: Linked
H5: e | I5: Recomputed
H6: h | I6: Immaterial. Hence ignored
B8: Other non current assets | C8: a | D8: b | E8: e | F8: e
B9: Particulars | C9: As at 31st March 20XX | D9: As at 31st March 20XX | E9: Variance | F9: Variance % | G9: Remarks
B11: Balances with government authorities (*)
B12: Capital advances
B13: Prepaid expenses
B14: Lease equalisation
B16: Total
B18: Trade receivables | C18: a | D18: b | E18: e | F18: e
B19: Particulars | C19: As at 31st March 20XX | D19: As at 31st March 20XX | E19: Variance | F19: Variance % | G19: Remarks
B21: Unsecured, considered good
B22: Unsecured, considered doubtful
B24: Less: Provision for doubtful receivables
B25: Receivables from related parties
B26: Unbilled receivables
B27: Total

Sheet 18-26
A1: =PL!A1 -> Client: | H1: Legend:
A2: Analysis of Notes to Accounts | H2: a | I2: Traced to Financials for the year ended 31 March 20XX
H3: b | I3: Traced to Financials for the year ended 31 March 20XX
H4: j | I4: Linked
H5: e | I5: Recomputed
H6: h | I6: Immaterial. Hence ignored
B11: Other Income | C11: a | D11: b | E11: e | F11: e
B12: Particulars | C12: As at 31st March 20XX | D12: As at 31st March 20XX | E12: Variance | F12: Variance % | G12: Remarks
B14: Gain on exchange fluctuations (net) | C14: 83032 | D14: 0 | E14: =C14-D14 -> 83032 | F14: =E14/D14 -> #DIV/0!
B15: Interest income from financial assets at amortised cost | C15: 0 | D15: 0 | E15: =C15-D15 -> 0 | F15: =E15/D15 -> #DIV/0!
B16: Profit on sale of mutual fund units | C16: 0 | D16: 0 | E16: =C16-D16 -> 0 | F16: =E16/D16 -> #DIV/0!
B17: Unrealised (loss) on mutual fund units | C17: 0 | D17: 0 | E17: =C17-D17 -> 0 | F17: =E17/D17 -> #DIV/0!
B18: Interest income under effective interest method on security deposit | C18: 217627 | D18: 188323 | E18: =C18-D18 -> 29304 | F18: =E18/D18 -> 0.155605
B19: Interest income from term deposits & others | C19: 15602768 | D19: 15754938 | E19: =C19-D19 -> -152170 | F19: =E19/D19 -> -0.0096585591
B20: Interest on income tax refund | C20: 0 | D20: 128810 | E20: =C20-D20 -> -128810 | F20: =E20/D20 -> -1
B21: Gain on disposal of property, plant and equipment, net | C21: 0 | D21: 0 | E21: =C21-D21 -> 0 | F21: =E21/D21 -> #DIV/0!
B22: Gain on modification of financial liability (refer note 11 and 28) | C22: 0 | D22: 20393931 | E22: =C22-D22 -> -20393931 | F22: =E22/D22 -> -1
B24: Total | C24: =SUM(C14:C22) -> 15903427 | D24: =SUM(D14:D22) -> 36466002 | E24: =SUM(E14:E22) -> -20562575

Sheet Ratio analysis
B1: =BS!A1 -> Client:
B2: Ratio Analysis
B3: As at 31 March XXX vs 31 March XXX
B5: Scope: Percentage variance of +/- 10% have been selected for analysis.
B7: KEY METRIC | C7: FORMULA | D7: 24-25 (CY) | E7: 23-24 (PY) | F7: CHANGE (%) | G7: REMARKS
B8: Debt Equity Ratio | C8: (LTB + STB) / Total Equity | F8: =IFERROR((D8-E8)/E8,0) -> 0
B9: Current Ratio | C9: Total Assets / Total Liabilities | F9: =IFERROR((D9-E9)/E9,0) -> 0
B10: GCA Days | C10: (Total CA / Total Revenue) * 365 | F10: =IFERROR((D10-E10)/E10,0) -> 0
B11: Total Outside Liab. vs Total Equity | C11: (TCL + TNCL) / Total Equity | F11: =IFERROR((D11-E11)/E11,0) -> 0
B12: Net Profit Ratio | C12: PBT / (Revenue from Ops + Unbilled Revenue) | F12: =IFERROR((D12-E12)/E12,0) -> 0
B13: Return on Equity (ROE) | C13: PBT / Avg. Total Equity | F13: =IFERROR((D13-E13)/E13,0) -> 0
B14: Return on Capital Employed (ROCE) | C14: (PBT - Finance Cost) / (TE + LTB + STB) | F14: =IFERROR((D14-E14)/E14,0) -> 0
B15: Debtor Turnover Ratio | C15: Revenue from Ops / Closing Debtors | F15: =IFERROR((D15-E15)/E15,0) -> 0

Sheet Sheet1
B3: =#REF! -> #REF! | C3: Export incentives pending | D3: Jalota/parmar
B222: The export incentives contains the duty scrips given as a reward by the government against the export of goods. The income over these scrips is booked by the Company the time when the revenue against the export sale over which duty scrip is granted is recognised i.e. when Bill of Lading is generated. These scrips can be utlised against import duty payments or can be further sold to any third party. During the current quarter, except deemed exports (made to countries like nepal, bhutan) the Company madde 145 all the 5 export sales were deemed export to Nepal only, hence no income is booked by the Company. Pass further analytical procedures.

Sheet Sheet2
C2: 31 December 2020 | D2: 30 September 2020 | E2: 31 December 2019 | F2: 30 September 2019
B3: Deposits with original maturity less than three months | D3: 2.9492648e+08
B4: Deposits with original maturity more than three months but remaining maturity less than twelve months | D4: 18700567
B5: Non-current bank balances | D5: 2155618
C6: =SUM(C3:C5) -> 0 | D6: =SUM(D3:D5) -> 3.1578266e+08 | E6: =SUM(E3:E5) -> 0 | F6: =SUM(F3:F5) -> 0
A8: Closing | B8: Mizuho | C8: 1300000000 | D8: 1900000000 | E8: 0 | F8: 245000000
A9: Closing | B9: HDFC | C9: 200000000 | D9: 200000000 | E9: 200000000 | F9: 200000000
A10: Closing | B10: Axis | C10: 400000000 | D10: 0 | E10: 0 | F10: 0
C11: =SUM(C8:C10) -> 1900000000 | D11: =SUM(D8:D10) -> 2100000000 | E11: =SUM(E8:E10) -> 200000000 | F11: =SUM(F8:F10) -> 445000000
A13: Average | B13: HDFC
A14: Average | B14: Mizuho
A15: Average | C15: =SUM(C13:C14) -> 0 | E15: =SUM(E13:E14) -> 0
A16: Average | B16: As per client
B19: Property, plant and equipment | C19: 4.6205133e+09 | E19: 4.5415749e+09
B20: Other intangible assets | C20: 8.2967857e+08 | E20: 2.1056362e+08
B21: Right of use assets | C21: 1.2165286e+08 | E21: 85437101
C22: =SUM(C19:C21) -> 5.5718447e+09 | E22: =SUM(E19:E21) -> 4.8375756e+09
B25: Electricity | C25: 27847516 | E25: 44092943
B26: Electricity Offices/Transit Houses | C26: 902002 | E26: 1538047
B27: Electricity Company Leased Houses | C27: 251623 | E27: 245095
C28: =SUM(C25:C27) -> 29001141 | E28: =SUM(E25:E27) -> 45876085
B29: Diesel-Genset | C29: 369447.64 | E29: 628464.84
B30: Diesel-Thermopac | C30: 7301670.6 | E30: 8151665.8
B31: Diesel Paint Shop | C31: 4482133.5 | E31: 7837067.5
C32: =SUM(C29:C31) -> 12153252 | E32: =SUM(E29:E31) -> 16617198
C34: =SUM(C35:C39) -> 9987221.1 | E34: =SUM(E35:E39) -> 55095897
B35: Foreign - Boarding & Lodging | C35: =C44+C43 -> 0 | E35: =E44+E43 -> 2885108.3
B36: Local - Boarding & Lodging | C36: =C46+C45+C49+C47+C48 -> 4386895.2 | E36: =E46+E45+E49+E47+E48 -> 41981509
B37: Bus hiring | C37: =C42+C41 -> 2912395 | E37: =E42+E41 -> 4230089
B38: Fuel Charges | C38: =C53+C52+C51+C50 -> 2687930.9 | E38: =E53+E52+E51+E50 -> 5999191.3
B41: Business Conveyance Staff | C41: 0 | E41: 239064
B42: Business Conveyance Bus Hiring | C42: 2912395 | E42: 3991025
B43: Trav.& Convey. Foreign - Fare & Lc | C43: 0 | E43: 723922
B44: Trav.& Convey. Foreign - Boarding & Lodging | C44: 0 | E44: 2161186.3
B45: Trav. & Convey. - Fare | C45: 285041.65 | E45: 13407572
B46: Trav. & Convey. - Boarding | C46: 1290028 | E46: 9000370.5
B47: Trav. & Convey. - Lodging | C47: 794999.52 | E47: 11330557
B48: Trav. & Convey. - Local Conveyance | C48: 1598409.9 | E48: 7203478.1
B49: Trav. & Convey. - Taxi | C49: 418416.19 | E49: 1039531.4
B50: Travelling Expenses Company Guests | C50: 0 | E50: 21335
...
